Workbook
Name CalStartYear: #REF!
Name CalStartYear: #REF!
Name Coll_per: #REF!
Name Coll_per: #REF!
Name Gas_Coll: #REF!
Name Gas_Coll: #REF!
Name HR_Coll: #REF!
Name HR_Coll: #REF!

Sheet Aztec Metered Load
A1: CUSTOMER'S METERED LOAD | C1: =SUM(C7:C726) -> 2792.038 | D1: City of Aztec Meter
D2: AZT4908O81 (1)
C3: Transmission Losses | D3: 0
C4: Transformer Losses | D4: 0
A5: HOUR BEGINS | B5: HOUR ENDS | C5: TOTAL METERED LOAD with LOSSES (MWs) | D5: =SUM(D7:D726) -> 2792038 | G5: HOUR BEGINS | H5: HOUR ENDS | J5: Aztec Load
A7: 45748 | B7: =$A7+1/24 -> 45748.042 | C7: =SUM(D7)/1000 -> 3.311 | D7: =J7*(1+$D$3)*(1+$D$4) -> 3311 | G7: =A7 -> 45748 | H7: =B7 -> 45748.042 | J7: 3311
A8: =$A7+1/24 -> 45748.042 | B8: =$A8+1/24 -> 45748.083 | C8: =SUM(D8)/1000 -> 3.3 | D8: =J8*(1+$D$3)*(1+$D$4) -> 3300 | G8: =A8 -> 45748.042 | H8: =B8 -> 45748.083 | J8: 3300
A9: =$A8+1/24 -> 45748.083 | B9: =$A9+1/24 -> 45748.125 | C9: =SUM(D9)/1000 -> 3.367 | D9: =J9*(1+$D$3)*(1+$D$4) -> 3367 | G9: =A9 -> 45748.083 | H9: =B9 -> 45748.125 | J9: 3367
A10: =$A9+1/24 -> 45748.125 | B10: =$A10+1/24 -> 45748.167 | C10: =SUM(D10)/1000 -> 3.49 | D10: =J10*(1+$D$3)*(1+$D$4) -> 3490 | G10: =A10 -> 45748.125 | H10: =B10 -> 45748.167 | J10: 3490
A11: =$A10+1/24 -> 45748.167 | B11: =$A11+1/24 -> 45748.208 | C11: =SUM(D11)/1000 -> 3.763 | D11: =J11*(1+$D$3)*(1+$D$4) -> 3763 | G11: =A11 -> 45748.167 | H11: =B11 -> 45748.208 | J11: 3763
A12: =$A11+1/24 -> 45748.208 | B12: =$A12+1/24 -> 45748.25 | C12: =SUM(D12)/1000 -> 4.457 | D12: =J12*(1+$D$3)*(1+$D$4) -> 4457 | G12: =A12 -> 45748.208 | H12: =B12 -> 45748.25 | J12: 4457
A13: =$A12+1/24 -> 45748.25 | B13: =$A13+1/24 -> 45748.292 | C13: =SUM(D13)/1000 -> 4.721 | D13: =J13*(1+$D$3)*(1+$D$4) -> 4721 | G13: =A13 -> 45748.25 | H13: =B13 -> 45748.292 | J13: 4721
A14: =$A13+1/24 -> 45748.292 | B14: =$A14+1/24 -> 45748.333 | C14: =SUM(D14)/1000 -> 4.806 | D14: =J14*(1+$D$3)*(1+$D$4) -> 4806 | G14: =A14 -> 45748.292 | H14: =B14 -> 45748.333 | J14: 4806
A15: =$A14+1/24 -> 45748.333 | B15: =$A15+1/24 -> 45748.375 | C15: =SUM(D15)/1000 -> 5.014 | D15: =J15*(1+$D$3)*(1+$D$4) -> 5014 | G15: =A15 -> 45748.333 | H15: =B15 -> 45748.375 | J15: 5014
A16: =$A15+1/24 -> 45748.375 | B16: =$A16+1/24 -> 45748.417 | C16: =SUM(D16)/1000 -> 5.162 | D16: =J16*(1+$D$3)*(1+$D$4) -> 5162 | G16: =A16 -> 45748.375 | H16: =B16 -> 45748.417 | J16: 5162
A17: =$A16+1/24 -> 45748.417 | B17: =$A17+1/24 -> 45748.458 | C17: =SUM(D17)/1000 -> 4.751 | D17: =J17*(1+$D$3)*(1+$D$4) -> 4751 | G17: =A17 -> 45748.417 | H17: =B17 -> 45748.458 | J17: 4751
A18: =$A17+1/24 -> 45748.458 | B18: =$A18+1/24 -> 45748.5 | C18: =SUM(D18)/1000 -> 4.254 | D18: =J18*(1+$D$3)*(1+$D$4) -> 4254 | G18: =A18 -> 45748.458 | H18: =B18 -> 45748.5 | J18: 4254
A19: =$A18+1/24 -> 45748.5 | B19: =$A19+1/24 -> 45748.542 | C19: =SUM(D19)/1000 -> 3.949 | D19: =J19*(1+$D$3)*(1+$D$4) -> 3949 | G19: =A19 -> 45748.5 | H19: =B19 -> 45748.542 | J19: 3949
... A726: =$A725+1/24 -> 45777.958 | B726: =$A726+1/24 -> 45778 | C726: =SUM(D726)/1000 -> 3.208 | D726: =J726*(1+$D$3)*(1+$D$4) -> 3208 | G726: =A726 -> 45777.958 | H726: =B726 -> 45778 | J726: 3208
B732: TOTAL | C732: =SUM(C7:C726) -> 2792.038 | D732: =SUM(D7:D726) -> 2792038
B734: CHECK | C734: =SUM(D732:D732)/1000 -> 2792.038

Sheet Solar
H1: 1 | I1: 2 | J1: 3 | K1: 4 | L1: 5 | M1: 6 | N1: 7 | O1: 8 | P1: 9 | Q1: 10 | R1: 11 | S1: 12 | T1: 13 | U1: 14 | V1: 15 | W1: 16 | X1: 17 | Y1: 18 | Z1: 19 | AA1: 20 | AB1: 21 | AC1: 22 | AD1: 23 | AE1: 24
B2: DATE | C2: HE | D2: KWh | E2: MWh
B3: 45748 | C3: 1 | D3: 0 | E3: =D3/1000 -> 0
B4: =IF(C3=24,B3+1,B3) -> 45748 | C4: =IF(C3=24,1,C3+1) -> 2 | D4: 0 | E4: =D4/1000 -> 0
B5: =IF(C4=24,B4+1,B4) -> 45748 | C5: =IF(C4=24,1,C4+1) -> 3 | D5: 0 | E5: =D5/1000 -> 0 | J5: HE 1 | K5: HE 2 | L5: HE 3 | M5: HE 4 | N5: HE 5 | O5: HE 6 | P5: HE 7 | Q5: HE 8 | R5: HE 9 | S5: HE 10 | T5: HE 11 | U5: HE 12 | V5: HE 13 | W5: HE 14 | X5: HE 15 | Y5: HE 16 | Z5: HE 17 | AA5: HE 18 | AB5: HE 19 | AC5: HE 20 | AD5: HE 21 | AE5: HE 22 | AF5: HE 23 | AG5: HE 24 | AH5: Grand Total
B6: =IF(C5=24,B5+1,B5) -> 45748 | C6: =IF(C5=24,1,C5+1) -> 4 | D6: 0 | E6: =D6/1000 -> 0 | I6: 45748 | J6: =SUMIFS($D$3:$D$746,$B$3:$B$746,$I6,$C$3:$C$746,H$1) -> 0 | K6: =SUMIFS($D$3:$D$746,$B$3:$B$746,$I6,$C$3:$C$746,I$1) -> 0 | L6: =SUMIFS($D$3:$D$746,$B$3:$B$746,$I6,$C$3:$C$746,J$1) -> 0 | M6: =SUMIFS($D$3:$D$746,$B$3:$B$746,$I6,$C$3:$C$746,K$1) -> 0 | N6: =SUMIFS($D$3:$D$746,$B$3:$B$746,$I6,$C$3:$C$746,L$1) -> 0 | O6: =SUMIFS($D$3:$D$746,$B$3:$B$746,$I6,$C$3:$C$746,M$1) -> 0 | P6: =SUMIFS($D$3:$D$746,$B$3:$B$746,$I6,$C$3:$C$746,N$1) -> 40 | Q6: =SUMIFS($D$3:$D$746,$B$3:$B$746,$I6,$C$3:$C$746,O$1) -> 125 | ... AG6: =SUMIFS($D$3:$D$746,$B$3:$B$746,$I6,$C$3:$C$746,AE$1) -> 0 | AH6: =SUM(J6:AG6) -> 3336
B7: =IF(C6=24,B6+1,B6) -> 45748 | C7: =IF(C6=24,1,C6+1) -> 5 | D7: 0 | E7: =D7/1000 -> 0 | I7: =I6+1 -> 45749 | J7: =SUMIFS($D$3:$D$746,$B$3:$B$746,$I7,$C$3:$C$746,H$1) -> 0 | K7: =SUMIFS($D$3:$D$746,$B$3:$B$746,$I7,$C$3:$C$746,I$1) -> 0 | L7: =SUMIFS($D$3:$D$746,$B$3:$B$746,$I7,$C$3:$C$746,J$1) -> 0 | M7: =SUMIFS($D$3:$D$746,$B$3:$B$746,$I7,$C$3:$C$746,K$1) -> 0 | N7: =SUMIFS($D$3:$D$746,$B$3:$B$746,$I7,$C$3:$C$746,L$1) -> 0 | O7: =SUMIFS($D$3:$D$746,$B$3:$B$746,$I7,$C$3:$C$746,M$1) -> 0 | P7: =SUMIFS($D$3:$D$746,$B$3:$B$746,$I7,$C$3:$C$746,N$1) -> 54 | Q7: =SUMIFS($D$3:$D$746,$B$3:$B$746,$I7,$C$3:$C$746,O$1) -> 284 | ... AG7: =SUMIFS($D$3:$D$746,$B$3:$B$746,$I7,$C$3:$C$746,AE$1) -> 0 | AH7: =SUM(J7:AG7) -> 5688
B8: =IF(C7=24,B7+1,B7) -> 45748 | C8: =IF(C7=24,1,C7+1) -> 6 | D8: 0 | E8: =D8/1000 -> 0 | I8: =I7+1 -> 45750 | J8: =SUMIFS($D$3:$D$746,$B$3:$B$746,$I8,$C$3:$C$746,H$1) -> 0 | K8: =SUMIFS($D$3:$D$746,$B$3:$B$746,$I8,$C$3:$C$746,I$1) -> 0 | L8: =SUMIFS($D$3:$D$746,$B$3:$B$746,$I8,$C$3:$C$746,J$1) -> 0 | M8: =SUMIFS($D$3:$D$746,$B$3:$B$746,$I8,$C$3:$C$746,K$1) -> 0 | N8: =SUMIFS($D$3:$D$746,$B$3:$B$746,$I8,$C$3:$C$746,L$1) -> 0 | O8: =SUMIFS($D$3:$D$746,$B$3:$B$746,$I8,$C$3:$C$746,M$1) -> 0 | P8: =SUMIFS($D$3:$D$746,$B$3:$B$746,$I8,$C$3:$C$746,N$1) -> 48 | Q8: =SUMIFS($D$3:$D$746,$B$3:$B$746,$I8,$C$3:$C$746,O$1) -> 268 | ... AG8: =SUMIFS($D$3:$D$746,$B$3:$B$746,$I8,$C$3:$C$746,AE$1) -> 0 | AH8: =SUM(J8:AG8) -> 5126
B9: =IF(C8=24,B8+1,B8) -> 45748 | C9: =IF(C8=24,1,C8+1) -> 7 | D9: 40 | E9: =D9/1000 -> 0.04 | I9: =I8+1 -> 45751 | J9: =SUMIFS($D$3:$D$746,$B$3:$B$746,$I9,$C$3:$C$746,H$1) -> 0 | K9: =SUMIFS($D$3:$D$746,$B$3:$B$746,$I9,$C$3:$C$746,I$1) -> 0 | L9: =SUMIFS($D$3:$D$746,$B$3:$B$746,$I9,$C$3:$C$746,J$1) -> 0 | M9: =SUMIFS($D$3:$D$746,$B$3:$B$746,$I9,$C$3:$C$746,K$1) -> 0 | N9: =SUMIFS($D$3:$D$746,$B$3:$B$746,$I9,$C$3:$C$746,L$1) -> 0 | O9: =SUMIFS($D$3:$D$746,$B$3:$B$746,$I9,$C$3:$C$746,M$1) -> 0 | P9: =SUMIFS($D$3:$D$746,$B$3:$B$746,$I9,$C$3:$C$746,N$1) -> 54 | Q9: =SUMIFS($D$3:$D$746,$B$3:$B$746,$I9,$C$3:$C$746,O$1) -> 272 | ... AG9: =SUMIFS($D$3:$D$746,$B$3:$B$746,$I9,$C$3:$C$746,AE$1) -> 0 | AH9: =SUM(J9:AG9) -> 5875
B10: =IF(C9=24,B9+1,B9) -> 45748 | C10: =IF(C9=24,1,C9+1) -> 8 | D10: 125 | E10: =D10/1000 -> 0.125 | I10: =I9+1 -> 45752 | J10: =SUMIFS($D$3:$D$746,$B$3:$B$746,$I10,$C$3:$C$746,H$1) -> 0 | K10: =SUMIFS($D$3:$D$746,$B$3:$B$746,$I10,$C$3:$C$746,I$1) -> 0 | L10: =SUMIFS($D$3:$D$746,$B$3:$B$746,$I10,$C$3:$C$746,J$1) -> 0 | M10: =SUMIFS($D$3:$D$746,$B$3:$B$746,$I10,$C$3:$C$746,K$1) -> 0 | N10: =SUMIFS($D$3:$D$746,$B$3:$B$746,$I10,$C$3:$C$746,L$1) -> 0 | O10: =SUMIFS($D$3:$D$746,$B$3:$B$746,$I10,$C$3:$C$746,M$1) -> 0 | P10: =SUMIFS($D$3:$D$746,$B$3:$B$746,$I10,$C$3:$C$746,N$1) -> 0 | Q10: =SUMIFS($D$3:$D$746,$B$3:$B$746,$I10,$C$3:$C$746,O$1) -> 36 | ... AG10: =SUMIFS($D$3:$D$746,$B$3:$B$746,$I10,$C$3:$C$746,AE$1) -> 0 | AH10: =SUM(J10:AG10) -> 3817
B11: =IF(C10=24,B10+1,B10) -> 45748 | C11: =IF(C10=24,1,C10+1) -> 9 | D11: 94 | E11: =D11/1000 -> 0.094 | I11: =I10+1 -> 45753 | J11: =SUMIFS($D$3:$D$746,$B$3:$B$746,$I11,$C$3:$C$746,H$1) -> 0 | K11: =SUMIFS($D$3:$D$746,$B$3:$B$746,$I11,$C$3:$C$746,I$1) -> 0 | L11: =SUMIFS($D$3:$D$746,$B$3:$B$746,$I11,$C$3:$C$746,J$1) -> 0 | M11: =SUMIFS($D$3:$D$746,$B$3:$B$746,$I11,$C$3:$C$746,K$1) -> 0 | N11: =SUMIFS($D$3:$D$746,$B$3:$B$746,$I11,$C$3:$C$746,L$1) -> 0 | O11: =SUMIFS($D$3:$D$746,$B$3:$B$746,$I11,$C$3:$C$746,M$1) -> 0 | P11: =SUMIFS($D$3:$D$746,$B$3:$B$746,$I11,$C$3:$C$746,N$1) -> 63 | Q11: =SUMIFS($D$3:$D$746,$B$3:$B$746,$I11,$C$3:$C$746,O$1) -> 297 | ... AG11: =SUMIFS($D$3:$D$746,$B$3:$B$746,$I11,$C$3:$C$746,AE$1) -> 0 | AH11: =SUM(J11:AG11) -> 5970
B12: =IF(C11=24,B11+1,B11) -> 45748 | C12: =IF(C11=24,1,C11+1) -> 10 | D12: 96 | E12: =D12/1000 -> 0.096 | I12: =I11+1 -> 45754 | J12: =SUMIFS($D$3:$D$746,$B$3:$B$746,$I12,$C$3:$C$746,H$1) -> 0 | K12: =SUMIFS($D$3:$D$746,$B$3:$B$746,$I12,$C$3:$C$746,I$1) -> 0 | L12: =SUMIFS($D$3:$D$746,$B$3:$B$746,$I12,$C$3:$C$746,J$1) -> 0 | M12: =SUMIFS($D$3:$D$746,$B$3:$B$746,$I12,$C$3:$C$746,K$1) -> 0 | N12: =SUMIFS($D$3:$D$746,$B$3:$B$746,$I12,$C$3:$C$746,L$1) -> 0 | O12: =SUMIFS($D$3:$D$746,$B$3:$B$746,$I12,$C$3:$C$746,M$1) -> 0 | P12: =SUMIFS($D$3:$D$746,$B$3:$B$746,$I12,$C$3:$C$746,N$1) -> 41 | Q12: =SUMIFS($D$3:$D$746,$B$3:$B$746,$I12,$C$3:$C$746,O$1) -> 192 | ... AG12: =SUMIFS($D$3:$D$746,$B$3:$B$746,$I12,$C$3:$C$746,AE$1) -> 0 | AH12: =SUM(J12:AG12) -> 4204
B13: =IF(C12=24,B12+1,B12) -> 45748 | C13: =IF(C12=24,1,C12+1) -> 11 | D13: 347 | E13: =D13/1000 -> 0.347 | I13: =I12+1 -> 45755 | J13: =SUMIFS($D$3:$D$746,$B$3:$B$746,$I13,$C$3:$C$746,H$1) -> 0 | K13: =SUMIFS($D$3:$D$746,$B$3:$B$746,$I13,$C$3:$C$746,I$1) -> 0 | L13: =SUMIFS($D$3:$D$746,$B$3:$B$746,$I13,$C$3:$C$746,J$1) -> 0 | M13: =SUMIFS($D$3:$D$746,$B$3:$B$746,$I13,$C$3:$C$746,K$1) -> 0 | N13: =SUMIFS($D$3:$D$746,$B$3:$B$746,$I13,$C$3:$C$746,L$1) -> 0 | O13: =SUMIFS($D$3:$D$746,$B$3:$B$746,$I13,$C$3:$C$746,M$1) -> 0 | P13: =SUMIFS($D$3:$D$746,$B$3:$B$746,$I13,$C$3:$C$746,N$1) -> 30 | Q13: =SUMIFS($D$3:$D$746,$B$3:$B$746,$I13,$C$3:$C$746,O$1) -> 172 | ... AG13: =SUMIFS($D$3:$D$746,$B$3:$B$746,$I13,$C$3:$C$746,AE$1) -> 0 | AH13: =SUM(J13:AG13) -> 3881
B14: =IF(C13=24,B13+1,B13) -> 45748 | C14: =IF(C13=24,1,C13+1) -> 12 | D14: 608 | E14: =D14/1000 -> 0.608 | I14: =I13+1 -> 45756 | J14: =SUMIFS($D$3:$D$746,$B$3:$B$746,$I14,$C$3:$C$746,H$1) -> 0 | K14: =SUMIFS($D$3:$D$746,$B$3:$B$746,$I14,$C$3:$C$746,I$1) -> 0 | L14: =SUMIFS($D$3:$D$746,$B$3:$B$746,$I14,$C$3:$C$746,J$1) -> 0 | M14: =SUMIFS($D$3:$D$746,$B$3:$B$746,$I14,$C$3:$C$746,K$1) -> 0 | N14: =SUMIFS($D$3:$D$746,$B$3:$B$746,$I14,$C$3:$C$746,L$1) -> 0 | O14: =SUMIFS($D$3:$D$746,$B$3:$B$746,$I14,$C$3:$C$746,M$1) -> 0 | P14: =SUMIFS($D$3:$D$746,$B$3:$B$746,$I14,$C$3:$C$746,N$1) -> 40 | Q14: =SUMIFS($D$3:$D$746,$B$3:$B$746,$I14,$C$3:$C$746,O$1) -> 188 | ... AG14: =SUMIFS($D$3:$D$746,$B$3:$B$746,$I14,$C$3:$C$746,AE$1) -> 0 | AH14: =SUM(J14:AG14) -> 4131
B15: =IF(C14=24,B14+1,B14) -> 45748 | C15: =IF(C14=24,1,C14+1) -> 13 | D15: 722 | E15: =D15/1000 -> 0.722 | I15: =I14+1 -> 45757 | J15: =SUMIFS($D$3:$D$746,$B$3:$B$746,$I15,$C$3:$C$746,H$1) -> 0 | K15: =SUMIFS($D$3:$D$746,$B$3:$B$746,$I15,$C$3:$C$746,I$1) -> 0 | L15: =SUMIFS($D$3:$D$746,$B$3:$B$746,$I15,$C$3:$C$746,J$1) -> 0 | M15: =SUMIFS($D$3:$D$746,$B$3:$B$746,$I15,$C$3:$C$746,K$1) -> 0 | N15: =SUMIFS($D$3:$D$746,$B$3:$B$746,$I15,$C$3:$C$746,L$1) -> 0 | O15: =SUMIFS($D$3:$D$746,$B$3:$B$746,$I15,$C$3:$C$746,M$1) -> 0 | P15: =SUMIFS($D$3:$D$746,$B$3:$B$746,$I15,$C$3:$C$746,N$1) -> 39 | Q15: =SUMIFS($D$3:$D$746,$B$3:$B$746,$I15,$C$3:$C$746,O$1) -> 187 | ... AG15: =SUMIFS($D$3:$D$746,$B$3:$B$746,$I15,$C$3:$C$746,AE$1) -> 0 | AH15: =SUM(J15:AG15) -> 4074
B16: =IF(C15=24,B15+1,B15) -> 45748 | C16: =IF(C15=24,1,C15+1) -> 14 | D16: 458 | E16: =D16/1000 -> 0.458 | I16: =I15+1 -> 45758 | J16: =SUMIFS($D$3:$D$746,$B$3:$B$746,$I16,$C$3:$C$746,H$1) -> 0 | K16: =SUMIFS($D$3:$D$746,$B$3:$B$746,$I16,$C$3:$C$746,I$1) -> 0 | L16: =SUMIFS($D$3:$D$746,$B$3:$B$746,$I16,$C$3:$C$746,J$1) -> 0 | M16: =SUMIFS($D$3:$D$746,$B$3:$B$746,$I16,$C$3:$C$746,K$1) -> 0 | N16: =SUMIFS($D$3:$D$746,$B$3:$B$746,$I16,$C$3:$C$746,L$1) -> 0 | O16: =SUMIFS($D$3:$D$746,$B$3:$B$746,$I16,$C$3:$C$746,M$1) -> 0 | P16: =SUMIFS($D$3:$D$746,$B$3:$B$746,$I16,$C$3:$C$746,N$1) -> 40 | Q16: =SUMIFS($D$3:$D$746,$B$3:$B$746,$I16,$C$3:$C$746,O$1) -> 189 | ... AG16: =SUMIFS($D$3:$D$746,$B$3:$B$746,$I16,$C$3:$C$746,AE$1) -> 0 | AH16: =SUM(J16:AG16) -> 3968
B17: =IF(C16=24,B16+1,B16) -> 45748 | C17: =IF(C16=24,1,C16+1) -> 15 | D17: 276 | E17: =D17/1000 -> 0.276 | I17: =I16+1 -> 45759 | J17: =SUMIFS($D$3:$D$746,$B$3:$B$746,$I17,$C$3:$C$746,H$1) -> 0 | K17: =SUMIFS($D$3:$D$746,$B$3:$B$746,$I17,$C$3:$C$746,I$1) -> 0 | L17: =SUMIFS($D$3:$D$746,$B$3:$B$746,$I17,$C$3:$C$746,J$1) -> 0 | M17: =SUMIFS($D$3:$D$746,$B$3:$B$746,$I17,$C$3:$C$746,K$1) -> 0 | N17: =SUMIFS($D$3:$D$746,$B$3:$B$746,$I17,$C$3:$C$746,L$1) -> 0 | O17: =SUMIFS($D$3:$D$746,$B$3:$B$746,$I17,$C$3:$C$746,M$1) -> 0 | P17: =SUMIFS($D$3:$D$746,$B$3:$B$746,$I17,$C$3:$C$746,N$1) -> 42 | Q17: =SUMIFS($D$3:$D$746,$B$3:$B$746,$I17,$C$3:$C$746,O$1) -> 197 | ... AG17: =SUMIFS($D$3:$D$746,$B$3:$B$746,$I17,$C$3:$C$746,AE$1) -> 0 | AH17: =SUM(J17:AG17) -> 3437
B18: =IF(C17=24,B17+1,B17) -> 45748 | C18: =IF(C17=24,1,C17+1) -> 16 | D18: 311 | E18: =D18/1000 -> 0.311 | I18: =I17+1 -> 45760 | J18: =SUMIFS($D$3:$D$746,$B$3:$B$746,$I18,$C$3:$C$746,H$1) -> 0 | K18: =SUMIFS($D$3:$D$746,$B$3:$B$746,$I18,$C$3:$C$746,I$1) -> 0 | L18: =SUMIFS($D$3:$D$746,$B$3:$B$746,$I18,$C$3:$C$746,J$1) -> 0 | M18: =SUMIFS($D$3:$D$746,$B$3:$B$746,$I18,$C$3:$C$746,K$1) -> 0 | N18: =SUMIFS($D$3:$D$746,$B$3:$B$746,$I18,$C$3:$C$746,L$1) -> 0 | O18: =SUMIFS($D$3:$D$746,$B$3:$B$746,$I18,$C$3:$C$746,M$1) -> 0 | P18: =SUMIFS($D$3:$D$746,$B$3:$B$746,$I18,$C$3:$C$746,N$1) -> 45 | Q18: =SUMIFS($D$3:$D$746,$B$3:$B$746,$I18,$C$3:$C$746,O$1) -> 187 | ... AG18: =SUMIFS($D$3:$D$746,$B$3:$B$746,$I18,$C$3:$C$746,AE$1) -> 0 | AH18: =SUM(J18:AG18) -> 3494
... B35: =IF(C34=24,B34+1,B34) -> 45749 | C35: =IF(C34=24,1,C34+1) -> 9 | D35: 501 | E35: =D35/1000 -> 0.501 | I35: =I34+1 -> 45777 | J35: =SUMIFS($D$3:$D$746,$B$3:$B$746,$I35,$C$3:$C$746,H$1) -> 0 | K35: =SUMIFS($D$3:$D$746,$B$3:$B$746,$I35,$C$3:$C$746,I$1) -> 0 | L35: =SUMIFS($D$3:$D$746,$B$3:$B$746,$I35,$C$3:$C$746,J$1) -> 0 | M35: =SUMIFS($D$3:$D$746,$B$3:$B$746,$I35,$C$3:$C$746,K$1) -> 0 | N35: =SUMIFS($D$3:$D$746,$B$3:$B$746,$I35,$C$3:$C$746,L$1) -> 0 | O35: =SUMIFS($D$3:$D$746,$B$3:$B$746,$I35,$C$3:$C$746,M$1) -> 4 | P35: =SUMIFS($D$3:$D$746,$B$3:$B$746,$I35,$C$3:$C$746,N$1) -> 81 | Q35: =SUMIFS($D$3:$D$746,$B$3:$B$746,$I35,$C$3:$C$746,O$1) -> 273 | ... AG35: =SUMIFS($D$3:$D$746,$B$3:$B$746,$I35,$C$3:$C$746,AE$1) -> 0 | AH35: =SUM(J35:AG35) -> 6597
B36: =IF(C35=24,B35+1,B35) -> 45749 | C36: =IF(C35=24,1,C35+1) -> 10 | D36: 643 | E36: =D36/1000 -> 0.643 | J36: =SUMIFS($D$3:$D$746,$B$3:$B$746,$I36,$C$3:$C$746,H$1) -> 0 | K36: =SUMIFS($D$3:$D$746,$B$3:$B$746,$I36,$C$3:$C$746,I$1) -> 0 | L36: =SUMIFS($D$3:$D$746,$B$3:$B$746,$I36,$C$3:$C$746,J$1) -> 0 | M36: =SUMIFS($D$3:$D$746,$B$3:$B$746,$I36,$C$3:$C$746,K$1) -> 0 | N36: =SUMIFS($D$3:$D$746,$B$3:$B$746,$I36,$C$3:$C$746,L$1) -> 0 | O36: =SUMIFS($D$3:$D$746,$B$3:$B$746,$I36,$C$3:$C$746,M$1) -> 0 | P36: =SUMIFS($D$3:$D$746,$B$3:$B$746,$I36,$C$3:$C$746,N$1) -> 0 | Q36: =SUMIFS($D$3:$D$746,$B$3:$B$746,$I36,$C$3:$C$746,O$1) -> 0 | ... AG36: =SUMIFS($D$3:$D$746,$B$3:$B$746,$I36,$C$3:$C$746,AE$1) -> 0 | AH36: =SUM(J36:AG36) -> 0
B37: =IF(C36=24,B36+1,B36) -> 45749 | C37: =IF(C36=24,1,C36+1) -> 11 | D37: 741 | E37: =D37/1000 -> 0.741 | AH37: =SUM(AH6:AH36) -> 133068
B38: =IF(C37=24,B37+1,B37) -> 45749 | C38: =IF(C37=24,1,C37+1) -> 12 | D38: 775 | E38: =D38/1000 -> 0.775
B39: =IF(C38=24,B38+1,B38) -> 45749 | C39: =IF(C38=24,1,C38+1) -> 13 | D39: 719 | E39: =D39/1000 -> 0.719
B40: =IF(C39=24,B39+1,B39) -> 45749 | C40: =IF(C39=24,1,C39+1) -> 14 | D40: 737 | E40: =D40/1000 -> 0.737
B41: =IF(C40=24,B40+1,B40) -> 45749 | C41: =IF(C40=24,1,C40+1) -> 15 | D41: 606 | E41: =D41/1000 -> 0.606
B42: =IF(C41=24,B41+1,B41) -> 45749 | C42: =IF(C41=24,1,C41+1) -> 16 | D42: 275 | E42: =D42/1000 -> 0.275
B43: =IF(C42=24,B42+1,B42) -> 45749 | C43: =IF(C42=24,1,C42+1) -> 17 | D43: 300 | E43: =D43/1000 -> 0.3
B44: =IF(C43=24,B43+1,B43) -> 45749 | C44: =IF(C43=24,1,C43+1) -> 18 | D44: 53 | E44: =D44/1000 -> 0.053
B45: =IF(C44=24,B44+1,B44) -> 45749 | C45: =IF(C44=24,1,C44+1) -> 19 | D45: 0 | E45: =D45/1000 -> 0
B46: =IF(C45=24,B45+1,B45) -> 45749 | C46: =IF(C45=24,1,C45+1) -> 20 | D46: 0 | E46: =D46/1000 -> 0
B47: =IF(C46=24,B46+1,B46) -> 45749 | C47: =IF(C46=24,1,C46+1) -> 21 | D47: 0 | E47: =D47/1000 -> 0
B48: =IF(C47=24,B47+1,B47) -> 45749 | C48: =IF(C47=24,1,C47+1) -> 22 | D48: 0 | E48: =D48/1000 -> 0
B49: =IF(C48=24,B48+1,B48) -> 45749 | C49: =IF(C48=24,1,C48+1) -> 23 | D49: 0 | E49: =D49/1000 -> 0
... B722: =IF(C721=24,B721+1,B721) -> 45777 | C722: =IF(C721=24,1,C721+1) -> 24 | D722: 0 | E722: =D722/1000 -> 0

Sheet GEServed
F1: =SUM(F3:F722) -> 3535 | G1: =SUM(G3:G722) -> 400 | H1: =SUM(H3:H722) -> 0 | I1: =SUM(I3:I722) -> 807 | J1: =SUM(J3:J722) -> 0 | K1: =SUM(K3:K722) -> 3935 | L1: =SUM(L3:L722) -> 2792.038 | N1: =L1-I1-H1-G1-(F1-I1) -> -1142.962
A2: Date | B2: HE | C2: isHoliday | D2: PeakHour | E2: PeakType | F2: GE Served | G2: AHP | H2: WRP | I2: WRP-Rep | J2: WRF-Rep | K2: Total Delivered | L2: Actual Load | O2: =F2 -> GE Served
A3: 45748 | B3: 1 | C3: =IFERROR(MATCH(A4,NERCHolidays!$B$2:$B$121,0),0) -> 0 | D3: =IF(AND(B3>=8,B3<=23),1,0) -> 0 | E3: =IF(OR(WEEKDAY(A3)=1,C3<>0),"OP",IF(D3=0,"OP","PK")) -> OP | F3: =VLOOKUP(A3,$O$3:$AN$34,B3+2,FALSE) -> 5 | G3: =VLOOKUP(A3,$O$107:$AM$138,B3+1,FALSE) -> 1 | H3: =VLOOKUP(A3,$O$142:$AM$173,B3+1,FALSE) -> 0 | I3: =VLOOKUP(A3,$O$39:$AN$70,B3+2,FALSE) -> 1 | J3: =VLOOKUP(A3,$O$73:$AN$104,B3+2,FALSE) -> 0 | K3: =VLOOKUP(A3,$O$175:$AM$206,B3+1,FALSE) -> 6 | L3: ='Aztec Metered Load'!C7 -> 3.311 | O3: # flow_date | P3: CP | Q3: HE 1 | R3: HE 2 | S3: HE 3 | T3: HE 4 | U3: HE 5 | V3: HE 6 | W3: HE 7 | X3: HE 8 | Y3: HE 9 | Z3: HE 10 | AA3: HE 11 | AB3: HE 12 | AC3: HE 13 | AD3: HE 14 | AE3: HE 15 | AF3: HE 16 | AG3: HE 17 | AH3: HE 18 | AI3: HE 19 | AJ3: HE 20 | AK3: HE 21 | AL3: HE 22 | AM3: HE 23 | AN3: HE 24 | AO3: TOTALS
A4: =IF(B3=24,A3+1,A3) -> 45748 | B4: =IF(B3=24,1,B3+1) -> 2 | C4: =IFERROR(MATCH(A5,NERCHolidays!$B$2:$B$121,0),0) -> 0 | D4: =IF(AND(B4>=8,B4<=23),1,0) -> 0 | E4: =IF(OR(WEEKDAY(A4)=1,C4<>0),"OP",IF(D4=0,"OP","PK")) -> OP | F4: =VLOOKUP(A4,$O$3:$AN$34,B4+2,FALSE) -> 5 | G4: =VLOOKUP(A4,$O$107:$AM$138,B4+1,FALSE) -> 1 | H4: =VLOOKUP(A4,$O$142:$AM$173,B4+1,FALSE) -> 0 | I4: =VLOOKUP(A4,$O$39:$AN$70,B4+2,FALSE) -> 1 | J4: =VLOOKUP(A4,$O$73:$AN$104,B4+2,FALSE) -> 0 | K4: =VLOOKUP(A4,$O$175:$AM$206,B4+1,FALSE) -> 6 | L4: ='Aztec Metered Load'!C8 -> 3.3 | O4: 45748 | P4: Aztec | Q4: 5 | R4: 5 | S4: 0 | T4: 5 | U4: 5 | V4: 5 | W4: 5 | X4: 5 | Y4: 5 | Z4: 5 | AA4: 5 | AB4: 5 | AC4: 5 | AD4: 5 | AE4: 5 | AF4: 5 | AG4: 5 | AH4: 5 | AI4: 5 | AJ4: 5 | AK4: 5 | AL4: 5 | AM4: 5 | AN4: 5 | AO4: =SUM(Q4:AN4) -> 115
A5: =IF(B4=24,A4+1,A4) -> 45748 | B5: =IF(B4=24,1,B4+1) -> 3 | C5: =IFERROR(MATCH(A6,NERCHolidays!$B$2:$B$121,0),0) -> 0 | D5: =IF(AND(B5>=8,B5<=23),1,0) -> 0 | E5: =IF(OR(WEEKDAY(A5)=1,C5<>0),"OP",IF(D5=0,"OP","PK")) -> OP | F5: =VLOOKUP(A5,$O$3:$AN$34,B5+2,FALSE) -> 0 | G5: =VLOOKUP(A5,$O$107:$AM$138,B5+1,FALSE) -> 1 | H5: =VLOOKUP(A5,$O$142:$AM$173,B5+1,FALSE) -> 0 | I5: =VLOOKUP(A5,$O$39:$AN$70,B5+2,FALSE) -> 2 | J5: =VLOOKUP(A5,$O$73:$AN$104,B5+2,FALSE) -> 0 | K5: =VLOOKUP(A5,$O$175:$AM$206,B5+1,FALSE) -> 1 | L5: ='Aztec Metered Load'!C9 -> 3.367 | O5: =O4+1 -> 45749 | P5: Aztec | Q5: 5 | R5: 5 | S5: 5 | T5: 5 | U5: 5 | V5: 5 | W5: 5 | X5: 5 | Y5: 5 | Z5: 5 | AA5: 5 | AB5: 5 | AC5: 5 | AD5: 5 | AE5: 5 | AF5: 5 | AG5: 5 | AH5: 5 | AI5: 5 | AJ5: 5 | AK5: 5 | AL5: 5 | AM5: 5 | AN5: 5 | AO5: =SUM(Q5:AN5) -> 120
A6: =IF(B5=24,A5+1,A5) -> 45748 | B6: =IF(B5=24,1,B5+1) -> 4 | C6: =IFERROR(MATCH(A7,NERCHolidays!$B$2:$B$121,0),0) -> 0 | D6: =IF(AND(B6>=8,B6<=23),1,0) -> 0 | E6: =IF(OR(WEEKDAY(A6)=1,C6<>0),"OP",IF(D6=0,"OP","PK")) -> OP | F6: =VLOOKUP(A6,$O$3:$AN$34,B6+2,FALSE) -> 5 | G6: =VLOOKUP(A6,$O$107:$AM$138,B6+1,FALSE) -> 1 | H6: =VLOOKUP(A6,$O$142:$AM$173,B6+1,FALSE) -> 0 | I6: =VLOOKUP(A6,$O$39:$AN$70,B6+2,FALSE) -> 2 | J6: =VLOOKUP(A6,$O$73:$AN$104,B6+2,FALSE) -> 0 | K6: =VLOOKUP(A6,$O$175:$AM$206,B6+1,FALSE) -> 6 | L6: ='Aztec Metered Load'!C10 -> 3.49 | O6: =O5+1 -> 45750 | P6: Aztec | Q6: 5 | R6: 5 | S6: 5 | T6: 5 | U6: 5 | V6: 5 | W6: 5 | X6: 1 | Y6: 1 | Z6: 5 | AA6: 5 | AB6: 5 | AC6: 5 | AD6: 5 | AE6: 5 | AF6: 5 | AG6: 5 | AH6: 0 | AI6: 5 | AJ6: 5 | AK6: 5 | AL6: 5 | AM6: 5 | AN6: 5 | AO6: =SUM(Q6:AN6) -> 107
A7: =IF(B6=24,A6+1,A6) -> 45748 | B7: =IF(B6=24,1,B6+1) -> 5 | C7: =IFERROR(MATCH(A8,NERCHolidays!$B$2:$B$121,0),0) -> 0 | D7: =IF(AND(B7>=8,B7<=23),1,0) -> 0 | E7: =IF(OR(WEEKDAY(A7)=1,C7<>0),"OP",IF(D7=0,"OP","PK")) -> OP | F7: =VLOOKUP(A7,$O$3:$AN$34,B7+2,FALSE) -> 5 | G7: =VLOOKUP(A7,$O$107:$AM$138,B7+1,FALSE) -> 1 | H7: =VLOOKUP(A7,$O$142:$AM$173,B7+1,FALSE) -> 0 | I7: =VLOOKUP(A7,$O$39:$AN$70,B7+2,FALSE) -> 2 | J7: =VLOOKUP(A7,$O$73:$AN$104,B7+2,FALSE) -> 0 | K7: =VLOOKUP(A7,$O$175:$AM$206,B7+1,FALSE) -> 6 | L7: ='Aztec Metered Load'!C11 -> 3.763 | O7: =O6+1 -> 45751 | P7: Aztec | Q7: 5 | R7: 5 | S7: 5 | T7: 5 | U7: 0 | V7: 0 | W7: 5 | X7: 5 | Y7: 5 | Z7: 5 | AA7: 5 | AB7: 5 | AC7: 5 | AD7: 5 | AE7: 5 | AF7: 5 | AG7: 5 | AH7: 5 | AI7: 5 | AJ7: 5 | AK7: 5 | AL7: 5 | AM7: 5 | AN7: 5 | AO7: =SUM(Q7:AN7) -> 110
A8: =IF(B7=24,A7+1,A7) -> 45748 | B8: =IF(B7=24,1,B7+1) -> 6 | C8: =IFERROR(MATCH(A9,NERCHolidays!$B$2:$B$121,0),0) -> 0 | D8: =IF(AND(B8>=8,B8<=23),1,0) -> 0 | E8: =IF(OR(WEEKDAY(A8)=1,C8<>0),"OP",IF(D8=0,"OP","PK")) -> OP | F8: =VLOOKUP(A8,$O$3:$AN$34,B8+2,FALSE) -> 5 | G8: =VLOOKUP(A8,$O$107:$AM$138,B8+1,FALSE) -> 1 | H8: =VLOOKUP(A8,$O$142:$AM$173,B8+1,FALSE) -> 0 | I8: =VLOOKUP(A8,$O$39:$AN$70,B8+2,FALSE) -> 2 | J8: =VLOOKUP(A8,$O$73:$AN$104,B8+2,FALSE) -> 0 | K8: =VLOOKUP(A8,$O$175:$AM$206,B8+1,FALSE) -> 6 | L8: ='Aztec Metered Load'!C12 -> 4.457 | O8: =O7+1 -> 45752 | P8: Aztec | Q8: 5 | R8: 5 | S8: 5 | T8: 5 | U8: 5 | V8: 5 | W8: 5 | X8: 5 | Y8: 5 | Z8: 5 | AA8: 5 | AB8: 5 | AC8: 5 | AD8: 5 | AE8: 5 | AF8: 5 | AG8: 5 | AH8: 5 | AI8: 5 | AJ8: 5 | AK8: 5 | AL8: 5 | AM8: 5 | AN8: 5 | AO8: =SUM(Q8:AN8) -> 120
A9: =IF(B8=24,A8+1,A8) -> 45748 | B9: =IF(B8=24,1,B8+1) -> 7 | C9: =IFERROR(MATCH(A10,NERCHolidays!$B$2:$B$121,0),0) -> 0 | D9: =IF(AND(B9>=8,B9<=23),1,0) -> 0 | E9: =IF(OR(WEEKDAY(A9)=1,C9<>0),"OP",IF(D9=0,"OP","PK")) -> OP | F9: =VLOOKUP(A9,$O$3:$AN$34,B9+2,FALSE) -> 5 | G9: =VLOOKUP(A9,$O$107:$AM$138,B9+1,FALSE) -> 1 | H9: =VLOOKUP(A9,$O$142:$AM$173,B9+1,FALSE) -> 0 | I9: =VLOOKUP(A9,$O$39:$AN$70,B9+2,FALSE) -> 1 | J9: =VLOOKUP(A9,$O$73:$AN$104,B9+2,FALSE) -> 0 | K9: =VLOOKUP(A9,$O$175:$AM$206,B9+1,FALSE) -> 6 | L9: ='Aztec Metered Load'!C13 -> 4.721 | O9: =O8+1 -> 45753 | P9: Aztec | Q9: 5 | R9: 5 | S9: 5 | T9: 5 | U9: 5 | V9: 5 | W9: 5 | X9: 5 | Y9: 5 | Z9: 5 | AA9: 5 | AB9: 5 | AC9: 5 | AD9: 5 | AE9: 5 | AF9: 5 | AG9: 5 | AH9: 5 | AI9: 5 | AJ9: 5 | AK9: 5 | AL9: 5 | AM9: 5 | AN9: 5 | AO9: =SUM(Q9:AN9) -> 120
A10: =IF(B9=24,A9+1,A9) -> 45748 | B10: =IF(B9=24,1,B9+1) -> 8 | C10: =IFERROR(MATCH(A11,NERCHolidays!$B$2:$B$121,0),0) -> 0 | D10: =IF(AND(B10>=8,B10<=23),1,0) -> 1 | E10: =IF(OR(WEEKDAY(A10)=1,C10<>0),"OP",IF(D10=0,"OP","PK")) -> PK | F10: =VLOOKUP(A10,$O$3:$AN$34,B10+2,FALSE) -> 5 | G10: =VLOOKUP(A10,$O$107:$AM$138,B10+1,FALSE) -> 1 | H10: =VLOOKUP(A10,$O$142:$AM$173,B10+1,FALSE) -> 0 | I10: =VLOOKUP(A10,$O$39:$AN$70,B10+2,FALSE) -> 1 | J10: =VLOOKUP(A10,$O$73:$AN$104,B10+2,FALSE) -> 0 | K10: =VLOOKUP(A10,$O$175:$AM$206,B10+1,FALSE) -> 6 | L10: ='Aztec Metered Load'!C14 -> 4.806 | O10: =O9+1 -> 45754 | P10: Aztec | Q10: 5 | R10: 5 | S10: 5 | T10: 5 | U10: 5 | V10: 5 | W10: 5 | X10: 5 | Y10: 5 | Z10: 5 | AA10: 5 | AB10: 5 | AC10: 5 | AD10: 5 | AE10: 5 | AF10: 5 | AG10: 5 | AH10: 5 | AI10: 5 | AJ10: 5 | AK10: 5 | AL10: 5 | AM10: 5 | AN10: 5 | AO10: =SUM(Q10:AN10) -> 120
A11: =IF(B10=24,A10+1,A10) -> 45748 | B11: =IF(B10=24,1,B10+1) -> 9 | C11: =IFERROR(MATCH(A12,NERCHolidays!$B$2:$B$121,0),0) -> 0 | D11: =IF(AND(B11>=8,B11<=23),1,0) -> 1 | E11: =IF(OR(WEEKDAY(A11)=1,C11<>0),"OP",IF(D11=0,"OP","PK")) -> PK | F11: =VLOOKUP(A11,$O$3:$AN$34,B11+2,FALSE) -> 5 | G11: =VLOOKUP(A11,$O$107:$AM$138,B11+1,FALSE) -> 1 | H11: =VLOOKUP(A11,$O$142:$AM$173,B11+1,FALSE) -> 0 | I11: =VLOOKUP(A11,$O$39:$AN$70,B11+2,FALSE) -> 1 | J11: =VLOOKUP(A11,$O$73:$AN$104,B11+2,FALSE) -> 0 | K11: =VLOOKUP(A11,$O$175:$AM$206,B11+1,FALSE) -> 6 | L11: ='Aztec Metered Load'!C15 -> 5.014 | O11: =O10+1 -> 45755 | P11: Aztec | Q11: 5 | R11: 5 | S11: 5 | T11: 5 | U11: 5 | V11: 5 | W11: 5 | X11: 5 | Y11: 5 | Z11: 5 | AA11: 5 | AB11: 5 | AC11: 5 | AD11: 5 | AE11: 5 | AF11: 5 | AG11: 5 | AH11: 5 | AI11: 5 | AJ11: 5 | AK11: 5 | AL11: 5 | AM11: 5 | AN11: 5 | AO11: =SUM(Q11:AN11) -> 120
A12: =IF(B11=24,A11+1,A11) -> 45748 | B12: =IF(B11=24,1,B11+1) -> 10 | C12: =IFERROR(MATCH(A13,NERCHolidays!$B$2:$B$121,0),0) -> 0 | D12: =IF(AND(B12>=8,B12<=23),1,0) -> 1 | E12: =IF(OR(WEEKDAY(A12)=1,C12<>0),"OP",IF(D12=0,"OP","PK")) -> PK | F12: =VLOOKUP(A12,$O$3:$AN$34,B12+2,FALSE) -> 5 | G12: =VLOOKUP(A12,$O$107:$AM$138,B12+1,FALSE) -> 0 | H12: =VLOOKUP(A12,$O$142:$AM$173,B12+1,FALSE) -> 0 | I12: =VLOOKUP(A12,$O$40:$AN$70,B12+2,FALSE) -> 1 | J12: =VLOOKUP(A12,$O$73:$AN$104,B12+2,FALSE) -> 0 | K12: =VLOOKUP(A12,$O$175:$AM$206,B12+1,FALSE) -> 5 | L12: ='Aztec Metered Load'!C16 -> 5.162 | O12: =O11+1 -> 45756 | P12: Aztec | Q12: 5 | R12: 5 | S12: 5 | T12: 5 | U12: 5 | V12: 5 | W12: 5 | X12: 5 | Y12: 5 | Z12: 5 | AA12: 5 | AB12: 5 | AC12: 5 | AD12: 5 | AE12: 5 | AF12: 5 | AG12: 5 | AH12: 5 | AI12: 5 | AJ12: 5 | AK12: 5 | AL12: 5 | AM12: 5 | AN12: 5 | AO12: =SUM(Q12:AN12) -> 120
A13: =IF(B12=24,A12+1,A12) -> 45748 | B13: =IF(B12=24,1,B12+1) -> 11 | C13: =IFERROR(MATCH(A14,NERCHolidays!$B$2:$B$121,0),0) -> 0 | D13: =IF(AND(B13>=8,B13<=23),1,0) -> 1 | E13: =IF(OR(WEEKDAY(A13)=1,C13<>0),"OP",IF(D13=0,"OP","PK")) -> PK | F13: =VLOOKUP(A13,$O$3:$AN$34,B13+2,FALSE) -> 5 | G13: =VLOOKUP(A13,$O$107:$AM$138,B13+1,FALSE) -> 0 | H13: =VLOOKUP(A13,$O$142:$AM$173,B13+1,FALSE) -> 0 | I13: =VLOOKUP(A13,$O$40:$AN$70,B13+2,FALSE) -> 1 | J13: =VLOOKUP(A13,$O$73:$AN$104,B13+2,FALSE) -> 0 | K13: =VLOOKUP(A13,$O$175:$AM$206,B13+1,FALSE) -> 5 | L13: ='Aztec Metered Load'!C17 -> 4.751 | O13: =O12+1 -> 45757 | P13: Aztec | Q13: 5 | R13: 5 | S13: 5 | T13: 5 | U13: 5 | V13: 5 | W13: 5 | X13: 5 | Y13: 5 | Z13: 5 | AA13: 5 | AB13: 5 | AC13: 5 | AD13: 5 | AE13: 5 | AF13: 5 | AG13: 5 | AH13: 5 | AI13: 5 | AJ13: 5 | AK13: 5 | AL13: 5 | AM13: 5 | AN13: 5 | AO13: =SUM(Q13:AN13) -> 120
A14: =IF(B13=24,A13+1,A13) -> 45748 | B14: =IF(B13=24,1,B13+1) -> 12 | C14: =IFERROR(MATCH(A15,NERCHolidays!$B$2:$B$121,0),0) -> 0 | D14: =IF(AND(B14>=8,B14<=23),1,0) -> 1 | E14: =IF(OR(WEEKDAY(A14)=1,C14<>0),"OP",IF(D14=0,"OP","PK")) -> PK | F14: =VLOOKUP(A14,$O$3:$AN$34,B14+2,FALSE) -> 5 | G14: =VLOOKUP(A14,$O$107:$AM$138,B14+1,FALSE) -> 0 | H14: =VLOOKUP(A14,$O$142:$AM$173,B14+1,FALSE) -> 0 | I14: =VLOOKUP(A14,$O$40:$AN$70,B14+2,FALSE) -> 1 | J14: =VLOOKUP(A14,$O$73:$AN$104,B14+2,FALSE) -> 0 | K14: =VLOOKUP(A14,$O$175:$AM$206,B14+1,FALSE) -> 5 | L14: ='Aztec Metered Load'!C18 -> 4.254 | O14: =O13+1 -> 45758 | P14: Aztec | Q14: 5 | R14: 5 | S14: 5 | T14: 5 | U14: 5 | V14: 5 | W14: 5 | X14: 5 | Y14: 5 | Z14: 5 | AA14: 5 | AB14: 5 | AC14: 5 | AD14: 5 | AE14: 5 | AF14: 5 | AG14: 5 | AH14: 5 | AI14: 5 | AJ14: 5 | AK14: 5 | AL14: 5 | AM14: 5 | AN14: 5 | AO14: =SUM(Q14:AN14) -> 120
A15: =IF(B14=24,A14+1,A14) -> 45748 | B15: =IF(B14=24,1,B14+1) -> 13 | C15: =IFERROR(MATCH(A16,NERCHolidays!$B$2:$B$121,0),0) -> 0 | D15: =IF(AND(B15>=8,B15<=23),1,0) -> 1 | E15: =IF(OR(WEEKDAY(A15)=1,C15<>0),"OP",IF(D15=0,"OP","PK")) -> PK | F15: =VLOOKUP(A15,$O$3:$AN$34,B15+2,FALSE) -> 5 | G15: =VLOOKUP(A15,$O$107:$AM$138,B15+1,FALSE) -> 0 | H15: =VLOOKUP(A15,$O$142:$AM$173,B15+1,FALSE) -> 0 | I15: =VLOOKUP(A15,$O$40:$AN$70,B15+2,FALSE) -> 1 | J15: =VLOOKUP(A15,$O$73:$AN$104,B15+2,FALSE) -> 0 | K15: =VLOOKUP(A15,$O$175:$AM$206,B15+1,FALSE) -> 5 | L15: ='Aztec Metered Load'!C19 -> 3.949 | O15: =O14+1 -> 45759 | P15: Aztec | Q15: 5 | R15: 5 | S15: 5 | T15: 5 | U15: 5 | V15: 5 | W15: 5 | X15: 5 | Y15: 5 | Z15: 5 | AA15: 5 | AB15: 5 | AC15: 5 | AD15: 5 | AE15: 5 | AF15: 5 | AG15: 5 | AH15: 5 | AI15: 5 | AJ15: 5 | AK15: 5 | AL15: 5 | AM15: 5 | AN15: 5 | AO15: =SUM(Q15:AN15) -> 120
A16: =IF(B15=24,A15+1,A15) -> 45748 | B16: =IF(B15=24,1,B15+1) -> 14 | C16: =IFERROR(MATCH(A17,NERCHolidays!$B$2:$B$121,0),0) -> 0 | D16: =IF(AND(B16>=8,B16<=23),1,0) -> 1 | E16: =IF(OR(WEEKDAY(A16)=1,C16<>0),"OP",IF(D16=0,"OP","PK")) -> PK | F16: =VLOOKUP(A16,$O$3:$AN$34,B16+2,FALSE) -> 5 | G16: =VLOOKUP(A16,$O$107:$AM$138,B16+1,FALSE) -> 0 | H16: =VLOOKUP(A16,$O$142:$AM$173,B16+1,FALSE) -> 0 | I16: =VLOOKUP(A16,$O$40:$AN$70,B16+2,FALSE) -> 1 | J16: =VLOOKUP(A16,$O$73:$AN$104,B16+2,FALSE) -> 0 | K16: =VLOOKUP(A16,$O$175:$AM$206,B16+1,FALSE) -> 5 | L16: ='Aztec Metered Load'!C20 -> 4.269 | O16: =O15+1 -> 45760 | P16: Aztec | Q16: 5 | R16: 5 | S16: 5 | T16: 5 | U16: 5 | V16: 5 | W16: 5 | X16: 5 | Y16: 5 | Z16: 5 | AA16: 5 | AB16: 5 | AC16: 5 | AD16: 5 | AE16: 5 | AF16: 5 | AG16: 5 | AH16: 5 | AI16: 5 | AJ16: 5 | AK16: 5 | AL16: 5 | AM16: 5 | AN16: 5 | AO16: =SUM(Q16:AN16) -> 120
A17: =IF(B16=24,A16+1,A16) -> 45748 | B17: =IF(B16=24,1,B16+1) -> 15 | C17: =IFERROR(MATCH(A18,NERCHolidays!$B$2:$B$121,0),0) -> 0 | D17: =IF(AND(B17>=8,B17<=23),1,0) -> 1 | E17: =IF(OR(WEEKDAY(A17)=1,C17<>0),"OP",IF(D17=0,"OP","PK")) -> PK | F17: =VLOOKUP(A17,$O$3:$AN$34,B17+2,FALSE) -> 5 | G17: =VLOOKUP(A17,$O$107:$AM$138,B17+1,FALSE) -> 0 | H17: =VLOOKUP(A17,$O$142:$AM$173,B17+1,FALSE) -> 0 | I17: =VLOOKUP(A17,$O$40:$AN$70,B17+2,FALSE) -> 1 | J17: =VLOOKUP(A17,$O$73:$AN$104,B17+2,FALSE) -> 0 | K17: =VLOOKUP(A17,$O$175:$AM$206,B17+1,FALSE) -> 5 | L17: ='Aztec Metered Load'!C21 -> 4.537 | O17: =O16+1 -> 45761 | P17: Aztec | Q17: 5 | R17: 5 | S17: 5 | T17: 5 | U17: 5 | V17: 5 | W17: 5 | X17: 3 | Y17: 5 | Z17: 5 | AA17: 5 | AB17: 5 | AC17: 5 | AD17: 5 | AE17: 5 | AF17: 5 | AG17: 5 | AH17: 5 | AI17: 5 | AJ17: 5 | AK17: 5 | AL17: 5 | AM17: 5 | AN17: 5 | AO17: =SUM(Q17:AN17) -> 118
A18: =IF(B17=24,A17+1,A17) -> 45748 | B18: =IF(B17=24,1,B17+1) -> 16 | C18: =IFERROR(MATCH(A19,NERCHolidays!$B$2:$B$121,0),0) -> 0 | D18: =IF(AND(B18>=8,B18<=23),1,0) -> 1 | E18: =IF(OR(WEEKDAY(A18)=1,C18<>0),"OP",IF(D18=0,"OP","PK")) -> PK | F18: =VLOOKUP(A18,$O$3:$AN$34,B18+2,FALSE) -> 5 | G18: =VLOOKUP(A18,$O$107:$AM$138,B18+1,FALSE) -> 0 | H18: =VLOOKUP(A18,$O$142:$AM$173,B18+1,FALSE) -> 0 | I18: =VLOOKUP(A18,$O$40:$AN$70,B18+2,FALSE) -> 1 | J18: =VLOOKUP(A18,$O$73:$AN$104,B18+2,FALSE) -> 0 | K18: =VLOOKUP(A18,$O$175:$AM$206,B18+1,FALSE) -> 5 | L18: ='Aztec Metered Load'!C22 -> 4.344 | O18: =O17+1 -> 45762 | P18: Aztec | Q18: 5 | R18: 5 | S18: 5 | T18: 4 | U18: 4 | V18: 4 | W18: 4 | X18: 4 | Y18: 5 | Z18: 5 | AA18: 5 | AB18: 5 | AC18: 5 | AD18: 5 | AE18: 5 | AF18: 5 | AG18: 5 | AH18: 5 | AI18: 5 | AJ18: 5 | AK18: 5 | AL18: 5 | AM18: 5 | AN18: 5 | AO18: =SUM(Q18:AN18) -> 115
A19: =IF(B18=24,A18+1,A18) -> 45748 | B19: =IF(B18=24,1,B18+1) -> 17 | C19: =IFERROR(MATCH(A20,NERCHolidays!$B$2:$B$121,0),0) -> 0 | D19: =IF(AND(B19>=8,B19<=23),1,0) -> 1 | E19: =IF(OR(WEEKDAY(A19)=1,C19<>0),"OP",IF(D19=0,"OP","PK")) -> PK | F19: =VLOOKUP(A19,$O$3:$AN$34,B19+2,FALSE) -> 5 | G19: =VLOOKUP(A19,$O$107:$AM$138,B19+1,FALSE) -> 0 | H19: =VLOOKUP(A19,$O$142:$AM$173,B19+1,FALSE) -> 0 | I19: =VLOOKUP(A19,$O$40:$AN$70,B19+2,FALSE) -> 1 | J19: =VLOOKUP(A19,$O$73:$AN$104,B19+2,FALSE) -> 0 | K19: =VLOOKUP(A19,$O$175:$AM$206,B19+1,FALSE) -> 5 | L19: ='Aztec Metered Load'!C23 -> 4.435 | O19: =O18+1 -> 45763 | P19: Aztec | Q19: 5 | R19: 5 | S19: 5 | T19: 5 | U19: 5 | V19: 5 | W19: 5 | X19: 5 | Y19: 5 | Z19: 5 | AA19: 5 | AB19: 5 | AC19: 5 | AD19: 5 | AE19: 5 | AF19: 5 | AG19: 5 | AH19: 5 | AI19: 5 | AJ19: 5 | AK19: 5 | AL19: 5 | AM19: 5 | AN19: 5 | AO19: =SUM(Q19:AN19) -> 120
A20: =IF(B19=24,A19+1,A19) -> 45748 | B20: =IF(B19=24,1,B19+1) -> 18 | C20: =IFERROR(MATCH(A21,NERCHolidays!$B$2:$B$121,0),0) -> 0 | D20: =IF(AND(B20>=8,B20<=23),1,0) -> 1 | E20: =IF(OR(WEEKDAY(A20)=1,C20<>0),"OP",IF(D20=0,"OP","PK")) -> PK | F20: =VLOOKUP(A20,$O$3:$AN$34,B20+2,FALSE) -> 5 | G20: =VLOOKUP(A20,$O$107:$AM$138,B20+1,FALSE) -> 0 | H20: =VLOOKUP(A20,$O$142:$AM$173,B20+1,FALSE) -> 0 | I20: =VLOOKUP(A20,$O$40:$AN$70,B20+2,FALSE) -> 1 | J20: =VLOOKUP(A20,$O$73:$AN$104,B20+2,FALSE) -> 0 | K20: =VLOOKUP(A20,$O$175:$AM$206,B20+1,FALSE) -> 5 | L20: ='Aztec Metered Load'!C24 -> 4.48 | O20: =O19+1 -> 45764 | P20: Aztec | Q20: 5 | R20: 5 | S20: 5 | T20: 5 | U20: 5 | V20: 5 | W20: 5 | X20: 5 | Y20: 5 | Z20: 5 | AA20: 5 | AB20: 5 | AC20: 5 | AD20: 5 | AE20: 5 | AF20: 5 | AG20: 5 | AH20: 5 | AI20: 5 | AJ20: 5 | AK20: 5 | AL20: 5 | AM20: 5 | AN20: 5 | AO20: =SUM(Q20:AN20) -> 120
A21: =IF(B20=24,A20+1,A20) -> 45748 | B21: =IF(B20=24,1,B20+1) -> 19 | C21: =IFERROR(MATCH(A22,NERCHolidays!$B$2:$B$121,0),0) -> 0 | D21: =IF(AND(B21>=8,B21<=23),1,0) -> 1 | E21: =IF(OR(WEEKDAY(A21)=1,C21<>0),"OP",IF(D21=0,"OP","PK")) -> PK | F21: =VLOOKUP(A21,$O$3:$AN$34,B21+2,FALSE) -> 5 | G21: =VLOOKUP(A21,$O$107:$AM$138,B21+1,FALSE) -> 1 | H21: =VLOOKUP(A21,$O$142:$AM$173,B21+1,FALSE) -> 0 | I21: =VLOOKUP(A21,$O$40:$AN$70,B21+2,FALSE) -> 1 | J21: =VLOOKUP(A21,$O$73:$AN$104,B21+2,FALSE) -> 0 | K21: =VLOOKUP(A21,$O$175:$AM$206,B21+1,FALSE) -> 6 | L21: ='Aztec Metered Load'!C25 -> 4.661 | O21: =O20+1 -> 45765 | P21: Aztec | Q21: 5 | R21: 5 | S21: 5 | T21: 5 | U21: 5 | V21: 5 | W21: 5 | X21: 5 | Y21: 5 | Z21: 5 | AA21: 5 | AB21: 5 | AC21: 5 | AD21: 5 | AE21: 5 | AF21: 5 | AG21: 5 | AH21: 5 | AI21: 5 | AJ21: 5 | AK21: 5 | AL21: 5 | AM21: 5 | AN21: 5 | AO21: =SUM(Q21:AN21) -> 120
A22: =IF(B21=24,A21+1,A21) -> 45748 | B22: =IF(B21=24,1,B21+1) -> 20 | C22: =IFERROR(MATCH(A23,NERCHolidays!$B$2:$B$121,0),0) -> 0 | D22: =IF(AND(B22>=8,B22<=23),1,0) -> 1 | E22: =IF(OR(WEEKDAY(A22)=1,C22<>0),"OP",IF(D22=0,"OP","PK")) -> PK | F22: =VLOOKUP(A22,$O$3:$AN$34,B22+2,FALSE) -> 5 | G22: =VLOOKUP(A22,$O$107:$AM$138,B22+1,FALSE) -> 1 | H22: =VLOOKUP(A22,$O$142:$AM$173,B22+1,FALSE) -> 0 | I22: =VLOOKUP(A22,$O$40:$AN$70,B22+2,FALSE) -> 1 | J22: =VLOOKUP(A22,$O$73:$AN$104,B22+2,FALSE) -> 0 | K22: =VLOOKUP(A22,$O$175:$AM$206,B22+1,FALSE) -> 6 | L22: ='Aztec Metered Load'!C26 -> 4.837 | O22: =O21+1 -> 45766 | P22: Aztec | Q22: 5 | R22: 0 | S22: 4 | T22: 5 | U22: 5 | V22: 5 | W22: 5 | X22: 5 | Y22: 0 | Z22: 5 | AA22: 5 | AB22: 5 | AC22: 5 | AD22: 5 | AE22: 5 | AF22: 5 | AG22: 5 | AH22: 0 | AI22: 5 | AJ22: 5 | AK22: 5 | AL22: 5 | AM22: 5 | AN22: 5 | AO22: =SUM(Q22:AN22) -> 104
A23: =IF(B22=24,A22+1,A22) -> 45748 | B23: =IF(B22=24,1,B22+1) -> 21 | C23: =IFERROR(MATCH(A24,NERCHolidays!$B$2:$B$121,0),0) -> 0 | D23: =IF(AND(B23>=8,B23<=23),1,0) -> 1 | E23: =IF(OR(WEEKDAY(A23)=1,C23<>0),"OP",IF(D23=0,"OP","PK")) -> PK | F23: =VLOOKUP(A23,$O$3:$AN$34,B23+2,FALSE) -> 5 | G23: =VLOOKUP(A23,$O$107:$AM$138,B23+1,FALSE) -> 1 | H23: =VLOOKUP(A23,$O$142:$AM$173,B23+1,FALSE) -> 0 | I23: =VLOOKUP(A23,$O$40:$AN$70,B23+2,FALSE) -> 1 | J23: =VLOOKUP(A23,$O$73:$AN$104,B23+2,FALSE) -> 0 | K23: =VLOOKUP(A23,$O$175:$AM$206,B23+1,FALSE) -> 6 | L23: ='Aztec Metered Load'!C27 -> 4.637 | O23: =O22+1 -> 45767 | P23: Aztec | Q23: 0 | R23: 5 | S23: 5 | T23: 5 | U23: 5 | V23: 5 | W23: 5 | X23: 5 | Y23: 5 | Z23: 5 | AA23: 5 | AB23: 5 | AC23: 5 | AD23: 5 | AE23: 5 | AF23: 5 | AG23: 5 | AH23: 5 | AI23: 5 | AJ23: 5 | AK23: 5 | AL23: 5 | AM23: 5 | AN23: 5 | AO23: =SUM(Q23:AN23) -> 115
... A33: =IF(B32=24,A32+1,A32) -> 45749 | B33: =IF(B32=24,1,B32+1) -> 7 | C33: =IFERROR(MATCH(A34,NERCHolidays!$B$2:$B$121,0),0) -> 0 | D33: =IF(AND(B33>=8,B33<=23),1,0) -> 0 | E33: =IF(OR(WEEKDAY(A33)=1,C33<>0),"OP",IF(D33=0,"OP","PK")) -> OP | F33: =VLOOKUP(A33,$O$3:$AN$34,B33+2,FALSE) -> 5 | G33: =VLOOKUP(A33,$O$107:$AM$138,B33+1,FALSE) -> 1 | H33: =VLOOKUP(A33,$O$142:$AM$173,B33+1,FALSE) -> 0 | I33: =VLOOKUP(A33,$O$40:$AN$70,B33+2,FALSE) -> 1 | J33: =VLOOKUP(A33,$O$73:$AN$104,B33+2,FALSE) -> 0 | K33: =VLOOKUP(A33,$O$175:$AM$206,B33+1,FALSE) -> 6 | L33: ='Aztec Metered Load'!C37 -> 5.495 | O33: =O32+1 -> 45777 | P33: Aztec | Q33: 4 | R33: 4 | S33: 4 | T33: 4 | U33: 4 | V33: 4 | W33: 5 | X33: 5 | Y33: 5 | Z33: 5 | AA33: 5 | AB33: 5 | AC33: 5 | AD33: 5 | AE33: 5 | AF33: 5 | AG33: 5 | AH33: 5 | AI33: 5 | AJ33: 5 | AK33: 5 | AL33: 5 | AM33: 4 | AN33: 4 | AO33: =SUM(Q33:AN33) -> 112
A34: =IF(B33=24,A33+1,A33) -> 45749 | B34: =IF(B33=24,1,B33+1) -> 8 | C34: =IFERROR(MATCH(A35,NERCHolidays!$B$2:$B$121,0),0) -> 0 | D34: =IF(AND(B34>=8,B34<=23),1,0) -> 1 | E34: =IF(OR(WEEKDAY(A34)=1,C34<>0),"OP",IF(D34=0,"OP","PK")) -> PK | F34: =VLOOKUP(A34,$O$3:$AN$34,B34+2,FALSE) -> 5 | G34: =VLOOKUP(A34,$O$107:$AM$138,B34+1,FALSE) -> 1 | H34: =VLOOKUP(A34,$O$142:$AM$173,B34+1,FALSE) -> 0 | I34: =VLOOKUP(A34,$O$40:$AN$70,B34+2,FALSE) -> 1 | J34: =VLOOKUP(A34,$O$73:$AN$104,B34+2,FALSE) -> 0 | K34: =VLOOKUP(A34,$O$175:$AM$206,B34+1,FALSE) -> 6 | L34: ='Aztec Metered Load'!C38 -> 5.203 | AO34: =SUM(Q34:AN34) -> 0
A35: =IF(B34=24,A34+1,A34) -> 45749 | B35: =IF(B34=24,1,B34+1) -> 9 | C35: =IFERROR(MATCH(A36,NERCHolidays!$B$2:$B$121,0),0) -> 0 | D35: =IF(AND(B35>=8,B35<=23),1,0) -> 1 | E35: =IF(OR(WEEKDAY(A35)=1,C35<>0),"OP",IF(D35=0,"OP","PK")) -> PK | F35: =VLOOKUP(A35,$O$3:$AN$34,B35+2,FALSE) -> 5 | G35: =VLOOKUP(A35,$O$107:$AM$138,B35+1,FALSE) -> 1 | H35: =VLOOKUP(A35,$O$142:$AM$173,B35+1,FALSE) -> 0 | I35: =VLOOKUP(A35,$O$40:$AN$70,B35+2,FALSE) -> 1 | J35: =VLOOKUP(A35,$O$73:$AN$104,B35+2,FALSE) -> 0 | K35: =VLOOKUP(A35,$O$175:$AM$206,B35+1,FALSE) -> 6 | L35: ='Aztec Metered Load'!C39 -> 4.929 | AO35: =SUM(AO4:AO34) -> 3535
A36: =IF(B35=24,A35+1,A35) -> 45749 | B36: =IF(B35=24,1,B35+1) -> 10 | C36: =IFERROR(MATCH(A37,NERCHolidays!$B$2:$B$121,0),0) -> 0 | D36: =IF(AND(B36>=8,B36<=23),1,0) -> 1 | E36: =IF(OR(WEEKDAY(A36)=1,C36<>0),"OP",IF(D36=0,"OP","PK")) -> PK | F36: =VLOOKUP(A36,$O$3:$AN$34,B36+2,FALSE) -> 5 | G36: =VLOOKUP(A36,$O$107:$AM$138,B36+1,FALSE) -> 0 | H36: =VLOOKUP(A36,$O$142:$AM$173,B36+1,FALSE) -> 0 | I36: =VLOOKUP(A36,$O$40:$AN$70,B36+2,FALSE) -> 1 | J36: =VLOOKUP(A36,$O$73:$AN$104,B36+2,FALSE) -> 0 | K36: =VLOOKUP(A36,$O$175:$AM$206,B36+1,FALSE) -> 5 | L36: ='Aztec Metered Load'!C40 -> 4.474
A37: =IF(B36=24,A36+1,A36) -> 45749 | B37: =IF(B36=24,1,B36+1) -> 11 | C37: =IFERROR(MATCH(A38,NERCHolidays!$B$2:$B$121,0),0) -> 0 | D37: =IF(AND(B37>=8,B37<=23),1,0) -> 1 | E37: =IF(OR(WEEKDAY(A37)=1,C37<>0),"OP",IF(D37=0,"OP","PK")) -> PK | F37: =VLOOKUP(A37,$O$3:$AN$34,B37+2,FALSE) -> 5 | G37: =VLOOKUP(A37,$O$107:$AM$138,B37+1,FALSE) -> 0 | H37: =VLOOKUP(A37,$O$142:$AM$173,B37+1,FALSE) -> 0 | I37: =VLOOKUP(A37,$O$40:$AN$70,B37+2,FALSE) -> 1 | J37: =VLOOKUP(A37,$O$73:$AN$104,B37+2,FALSE) -> 0 | K37: =VLOOKUP(A37,$O$175:$AM$206,B37+1,FALSE) -> 5 | L37: ='Aztec Metered Load'!C41 -> 4.202
A38: =IF(B37=24,A37+1,A37) -> 45749 | B38: =IF(B37=24,1,B37+1) -> 12 | C38: =IFERROR(MATCH(A39,NERCHolidays!$B$2:$B$121,0),0) -> 0 | D38: =IF(AND(B38>=8,B38<=23),1,0) -> 1 | E38: =IF(OR(WEEKDAY(A38)=1,C38<>0),"OP",IF(D38=0,"OP","PK")) -> PK | F38: =VLOOKUP(A38,$O$3:$AN$34,B38+2,FALSE) -> 5 | G38: =VLOOKUP(A38,$O$107:$AM$138,B38+1,FALSE) -> 0 | H38: =VLOOKUP(A38,$O$142:$AM$173,B38+1,FALSE) -> 0 | I38: =VLOOKUP(A38,$O$40:$AN$70,B38+2,FALSE) -> 1 | J38: =VLOOKUP(A38,$O$73:$AN$104,B38+2,FALSE) -> 0 | K38: =VLOOKUP(A38,$O$175:$AM$206,B38+1,FALSE) -> 5 | L38: ='Aztec Metered Load'!C42 -> 3.934 | O38: WRP-Replacement
A39: =IF(B38=24,A38+1,A38) -> 45749 | B39: =IF(B38=24,1,B38+1) -> 13 | C39: =IFERROR(MATCH(A40,NERCHolidays!$B$2:$B$121,0),0) -> 0 | D39: =IF(AND(B39>=8,B39<=23),1,0) -> 1 | E39: =IF(OR(WEEKDAY(A39)=1,C39<>0),"OP",IF(D39=0,"OP","PK")) -> PK | F39: =VLOOKUP(A39,$O$3:$AN$34,B39+2,FALSE) -> 5 | G39: =VLOOKUP(A39,$O$107:$AM$138,B39+1,FALSE) -> 0 | H39: =VLOOKUP(A39,$O$142:$AM$173,B39+1,FALSE) -> 0 | I39: =VLOOKUP(A39,$O$40:$AN$70,B39+2,FALSE) -> 1 | J39: =VLOOKUP(A39,$O$73:$AN$104,B39+2,FALSE) -> 0 | K39: =VLOOKUP(A39,$O$175:$AM$206,B39+1,FALSE) -> 5 | L39: ='Aztec Metered Load'!C43 -> 4.004 | P39: Day | Q39: HE 1 | R39: HE 2 | S39: HE 3 | T39: HE 4 | U39: HE 5 | V39: HE 6 | W39: HE 7 | X39: HE 8 | Y39: HE 9 | Z39: HE 10 | AA39: HE 11 | AB39: HE 12 | AC39: HE 13 | AD39: HE 14 | AE39: HE 15 | AF39: HE 16 | AG39: HE 17 | AH39: HE 18 | AI39: HE 19 | AJ39: HE 20 | AK39: HE 21 | AL39: HE 22 | AM39: HE 23 | AN39: HE 24 | AO39: TOTALS | AP39: On-Peak | AQ39: Off-Peak
A40: =IF(B39=24,A39+1,A39) -> 45749 | B40: =IF(B39=24,1,B39+1) -> 14 | C40: =IFERROR(MATCH(A41,NERCHolidays!$B$2:$B$121,0),0) -> 0 | D40: =IF(AND(B40>=8,B40<=23),1,0) -> 1 | E40: =IF(OR(WEEKDAY(A40)=1,C40<>0),"OP",IF(D40=0,"OP","PK")) -> PK | F40: =VLOOKUP(A40,$O$3:$AN$34,B40+2,FALSE) -> 5 | G40: =VLOOKUP(A40,$O$107:$AM$138,B40+1,FALSE) -> 0 | H40: =VLOOKUP(A40,$O$142:$AM$173,B40+1,FALSE) -> 0 | I40: =VLOOKUP(A40,$O$40:$AN$70,B40+2,FALSE) -> 1 | J40: =VLOOKUP(A40,$O$73:$AN$104,B40+2,FALSE) -> 0 | K40: =VLOOKUP(A40,$O$175:$AM$206,B40+1,FALSE) -> 5 | L40: ='Aztec Metered Load'!C44 -> 3.866 | O40: =O4 -> 45748 | P40: 3 | Q40: 1 | R40: 1 | S40: 2 | T40: 2 | U40: 2 | V40: 2 | W40: 1 | X40: 1 | Y40: 1 | Z40: 1 | AA40: 1 | AB40: 1 | AC40: 1 | AD40: 1 | AE40: 1 | AF40: 1 | AG40: 1 | AH40: 1 | AI40: 1 | AJ40: 1 | AK40: 1 | AL40: 1 | AM40: 1 | AN40: 1 | AO40: =SUM(Q40:AN40) -> 28 | AP40: =IF(P40="SUNDAY",0,SUM(X40:AM40)) -> 16 | AQ40: =IF(P40="SUNDAY",SUM(Q40:AN40),SUM(Q40:W40,AN40:AN40)) -> 12
A41: =IF(B40=24,A40+1,A40) -> 45749 | B41: =IF(B40=24,1,B40+1) -> 15 | C41: =IFERROR(MATCH(A42,NERCHolidays!$B$2:$B$121,0),0) -> 0 | D41: =IF(AND(B41>=8,B41<=23),1,0) -> 1 | E41: =IF(OR(WEEKDAY(A41)=1,C41<>0),"OP",IF(D41=0,"OP","PK")) -> PK | F41: =VLOOKUP(A41,$O$3:$AN$34,B41+2,FALSE) -> 5 | G41: =VLOOKUP(A41,$O$107:$AM$138,B41+1,FALSE) -> 0 | H41: =VLOOKUP(A41,$O$142:$AM$173,B41+1,FALSE) -> 0 | I41: =VLOOKUP(A41,$O$40:$AN$70,B41+2,FALSE) -> 1 | J41: =VLOOKUP(A41,$O$73:$AN$104,B41+2,FALSE) -> 0 | K41: =VLOOKUP(A41,$O$175:$AM$206,B41+1,FALSE) -> 5 | L41: ='Aztec Metered Load'!C45 -> 3.914 | O41: =O5 -> 45749 | P41: 4 | Q41: 1 | R41: 1 | S41: 2 | T41: 2 | U41: 2 | V41: 2 | W41: 1 | X41: 1 | Y41: 1 | Z41: 1 | AA41: 1 | AB41: 1 | AC41: 1 | AD41: 1 | AE41: 1 | AF41: 1 | AG41: 1 | AH41: 1 | AI41: 1 | AJ41: 1 | AK41: 1 | AL41: 1 | AM41: 1 | AN41: 1 | AO41: =SUM(Q41:AN41) -> 28 | AP41: =IF(P41="SUNDAY",0,SUM(X41:AM41)) -> 16 | AQ41: =IF(P41="SUNDAY",SUM(Q41:AN41),SUM(Q41:W41,AN41:AN41)) -> 12
A42: =IF(B41=24,A41+1,A41) -> 45749 | B42: =IF(B41=24,1,B41+1) -> 16 | C42: =IFERROR(MATCH(A43,NERCHolidays!$B$2:$B$121,0),0) -> 0 | D42: =IF(AND(B42>=8,B42<=23),1,0) -> 1 | E42: =IF(OR(WEEKDAY(A42)=1,C42<>0),"OP",IF(D42=0,"OP","PK")) -> PK | F42: =VLOOKUP(A42,$O$3:$AN$34,B42+2,FALSE) -> 5 | G42: =VLOOKUP(A42,$O$107:$AM$138,B42+1,FALSE) -> 0 | H42: =VLOOKUP(A42,$O$142:$AM$173,B42+1,FALSE) -> 0 | I42: =VLOOKUP(A42,$O$40:$AN$70,B42+2,FALSE) -> 1 | J42: =VLOOKUP(A42,$O$73:$AN$104,B42+2,FALSE) -> 0 | K42: =VLOOKUP(A42,$O$175:$AM$206,B42+1,FALSE) -> 5 | L42: ='Aztec Metered Load'!C46 -> 4.325 | O42: =O6 -> 45750 | P42: 5 | Q42: 1 | R42: 1 | S42: 2 | T42: 2 | U42: 2 | V42: 2 | W42: 1 | X42: 1 | Y42: 1 | Z42: 1 | AA42: 1 | AB42: 1 | AC42: 1 | AD42: 1 | AE42: 1 | AF42: 1 | AG42: 1 | AH42: 1 | AI42: 1 | AJ42: 1 | AK42: 1 | AL42: 1 | AM42: 1 | AN42: 1 | AO42: =SUM(Q42:AN42) -> 28 | AP42: =IF(P42="SUNDAY",0,SUM(X42:AM42)) -> 16 | AQ42: =IF(P42="SUNDAY",SUM(Q42:AN42),SUM(Q42:W42,AN42:AN42)) -> 12
A43: =IF(B42=24,A42+1,A42) -> 45749 | B43: =IF(B42=24,1,B42+1) -> 17 | C43: =IFERROR(MATCH(A44,NERCHolidays!$B$2:$B$121,0),0) -> 0 | D43: =IF(AND(B43>=8,B43<=23),1,0) -> 1 | E43: =IF(OR(WEEKDAY(A43)=1,C43<>0),"OP",IF(D43=0,"OP","PK")) -> PK | F43: =VLOOKUP(A43,$O$3:$AN$34,B43+2,FALSE) -> 5 | G43: =VLOOKUP(A43,$O$107:$AM$138,B43+1,FALSE) -> 0 | H43: =VLOOKUP(A43,$O$142:$AM$173,B43+1,FALSE) -> 0 | I43: =VLOOKUP(A43,$O$40:$AN$70,B43+2,FALSE) -> 1 | J43: =VLOOKUP(A43,$O$73:$AN$104,B43+2,FALSE) -> 0 | K43: =VLOOKUP(A43,$O$175:$AM$206,B43+1,FALSE) -> 5 | L43: ='Aztec Metered Load'!C47 -> 3.986 | O43: =O7 -> 45751 | P43: 6 | Q43: 1 | R43: 1 | S43: 2 | T43: 2 | U43: 2 | V43: 2 | W43: 1 | X43: 1 | Y43: 1 | Z43: 1 | AA43: 1 | AB43: 1 | AC43: 1 | AD43: 1 | AE43: 1 | AF43: 1 | AG43: 1 | AH43: 1 | AI43: 1 | AJ43: 1 | AK43: 1 | AL43: 1 | AM43: 1 | AN43: 1 | AO43: =SUM(Q43:AN43) -> 28 | AP43: =IF(P43="SUNDAY",0,SUM(X43:AM43)) -> 16 | AQ43: =IF(P43="SUNDAY",SUM(Q43:AN43),SUM(Q43:W43,AN43:AN43)) -> 12
A44: =IF(B43=24,A43+1,A43) -> 45749 | B44: =IF(B43=24,1,B43+1) -> 18 | C44: =IFERROR(MATCH(A45,NERCHolidays!$B$2:$B$121,0),0) -> 0 | D44: =IF(AND(B44>=8,B44<=23),1,0) -> 1 | E44: =IF(OR(WEEKDAY(A44)=1,C44<>0),"OP",IF(D44=0,"OP","PK")) -> PK | F44: =VLOOKUP(A44,$O$3:$AN$34,B44+2,FALSE) -> 5 | G44: =VLOOKUP(A44,$O$107:$AM$138,B44+1,FALSE) -> 0 | H44: =VLOOKUP(A44,$O$142:$AM$173,B44+1,FALSE) -> 0 | I44: =VLOOKUP(A44,$O$40:$AN$70,B44+2,FALSE) -> 1 | J44: =VLOOKUP(A44,$O$73:$AN$104,B44+2,FALSE) -> 0 | K44: =VLOOKUP(A44,$O$175:$AM$206,B44+1,FALSE) -> 5 | L44: ='Aztec Metered Load'!C48 -> 4.298 | O44: =O8 -> 45752 | P44: 7 | Q44: 1 | R44: 1 | S44: 2 | T44: 2 | U44: 2 | V44: 2 | W44: 1 | X44: 1 | Y44: 1 | Z44: 1 | AA44: 1 | AB44: 1 | AC44: 1 | AD44: 1 | AE44: 1 | AF44: 1 | AG44: 1 | AH44: 1 | AI44: 1 | AJ44: 1 | AK44: 1 | AL44: 1 | AM44: 1 | AN44: 1 | AO44: =SUM(Q44:AN44) -> 28 | AP44: =IF(P44="SUNDAY",0,SUM(X44:AM44)) -> 16 | AQ44: =IF(P44="SUNDAY",SUM(Q44:AN44),SUM(Q44:W44,AN44:AN44)) -> 12
A45: =IF(B44=24,A44+1,A44) -> 45749 | B45: =IF(B44=24,1,B44+1) -> 19 | C45: =IFERROR(MATCH(A46,NERCHolidays!$B$2:$B$121,0),0) -> 0 | D45: =IF(AND(B45>=8,B45<=23),1,0) -> 1 | E45: =IF(OR(WEEKDAY(A45)=1,C45<>0),"OP",IF(D45=0,"OP","PK")) -> PK | F45: =VLOOKUP(A45,$O$3:$AN$34,B45+2,FALSE) -> 5 | G45: =VLOOKUP(A45,$O$107:$AM$138,B45+1,FALSE) -> 1 | H45: =VLOOKUP(A45,$O$142:$AM$173,B45+1,FALSE) -> 0 | I45: =VLOOKUP(A45,$O$40:$AN$70,B45+2,FALSE) -> 1 | J45: =VLOOKUP(A45,$O$73:$AN$104,B45+2,FALSE) -> 0 | K45: =VLOOKUP(A45,$O$175:$AM$206,B45+1,FALSE) -> 6 | L45: ='Aztec Metered Load'!C49 -> 4.708 | O45: =O9 -> 45753 | P45: Sunday | Q45: 1 | R45: 1 | S45: 2 | T45: 2 | U45: 2 | V45: 2 | W45: 1 | X45: 1 | Y45: 1 | Z45: 1 | AA45: 1 | AB45: 1 | AC45: 1 | AD45: 1 | AE45: 1 | AF45: 1 | AG45: 1 | AH45: 1 | AI45: 1 | AJ45: 1 | AK45: 1 | AL45: 1 | AM45: 1 | AN45: 1 | AO45: =SUM(Q45:AN45) -> 28 | AP45: =IF(P45="SUNDAY",0,SUM(X45:AM45)) -> 0 | AQ45: =IF(P45="SUNDAY",SUM(Q45:AN45),SUM(Q45:W45,AN45:AN45)) -> 28
A46: =IF(B45=24,A45+1,A45) -> 45749 | B46: =IF(B45=24,1,B45+1) -> 20 | C46: =IFERROR(MATCH(A47,NERCHolidays!$B$2:$B$121,0),0) -> 0 | D46: =IF(AND(B46>=8,B46<=23),1,0) -> 1 | E46: =IF(OR(WEEKDAY(A46)=1,C46<>0),"OP",IF(D46=0,"OP","PK")) -> PK | F46: =VLOOKUP(A46,$O$3:$AN$34,B46+2,FALSE) -> 5 | G46: =VLOOKUP(A46,$O$107:$AM$138,B46+1,FALSE) -> 1 | H46: =VLOOKUP(A46,$O$142:$AM$173,B46+1,FALSE) -> 0 | I46: =VLOOKUP(A46,$O$40:$AN$70,B46+2,FALSE) -> 1 | J46: =VLOOKUP(A46,$O$73:$AN$104,B46+2,FALSE) -> 0 | K46: =VLOOKUP(A46,$O$175:$AM$206,B46+1,FALSE) -> 6 | L46: ='Aztec Metered Load'!C50 -> 4.646 | O46: =O10 -> 45754 | P46: 2 | Q46: 1 | R46: 1 | S46: 2 | T46: 2 | U46: 2 | V46: 2 | W46: 1 | X46: 1 | Y46: 1 | Z46: 1 | AA46: 1 | AB46: 1 | AC46: 1 | AD46: 1 | AE46: 1 | AF46: 1 | AG46: 1 | AH46: 1 | AI46: 1 | AJ46: 1 | AK46: 1 | AL46: 1 | AM46: 1 | AN46: 1 | AO46: =SUM(Q46:AN46) -> 28 | AP46: =IF(P46="SUNDAY",0,SUM(X46:AM46)) -> 16 | AQ46: =IF(P46="SUNDAY",SUM(Q46:AN46),SUM(Q46:W46,AN46:AN46)) -> 12
A47: =IF(B46=24,A46+1,A46) -> 45749 | B47: =IF(B46=24,1,B46+1) -> 21 | C47: =IFERROR(MATCH(A48,NERCHolidays!$B$2:$B$121,0),0) -> 0 | D47: =IF(AND(B47>=8,B47<=23),1,0) -> 1 | E47: =IF(OR(WEEKDAY(A47)=1,C47<>0),"OP",IF(D47=0,"OP","PK")) -> PK | F47: =VLOOKUP(A47,$O$3:$AN$34,B47+2,FALSE) -> 5 | G47: =VLOOKUP(A47,$O$107:$AM$138,B47+1,FALSE) -> 1 | H47: =VLOOKUP(A47,$O$142:$AM$173,B47+1,FALSE) -> 0 | I47: =VLOOKUP(A47,$O$40:$AN$70,B47+2,FALSE) -> 1 | J47: =VLOOKUP(A47,$O$73:$AN$104,B47+2,FALSE) -> 0 | K47: =VLOOKUP(A47,$O$175:$AM$206,B47+1,FALSE) -> 6 | L47: ='Aztec Metered Load'!C51 -> 4.529 | O47: =O11 -> 45755 | P47: 3 | Q47: 1 | R47: 1 | S47: 2 | T47: 2 | U47: 2 | V47: 2 | W47: 1 | X47: 1 | Y47: 1 | Z47: 1 | AA47: 1 | AB47: 1 | AC47: 1 | AD47: 1 | AE47: 1 | AF47: 1 | AG47: 1 | AH47: 1 | AI47: 1 | AJ47: 1 | AK47: 1 | AL47: 1 | AM47: 1 | AN47: 1 | AO47: =SUM(Q47:AN47) -> 28 | AP47: =IF(P47="SUNDAY",0,SUM(X47:AM47)) -> 16 | AQ47: =IF(P47="SUNDAY",SUM(Q47:AN47),SUM(Q47:W47,AN47:AN47)) -> 12
A48: =IF(B47=24,A47+1,A47) -> 45749 | B48: =IF(B47=24,1,B47+1) -> 22 | C48: =IFERROR(MATCH(A49,NERCHolidays!$B$2:$B$121,0),0) -> 0 | D48: =IF(AND(B48>=8,B48<=23),1,0) -> 1 | E48: =IF(OR(WEEKDAY(A48)=1,C48<>0),"OP",IF(D48=0,"OP","PK")) -> PK | F48: =VLOOKUP(A48,$O$3:$AN$34,B48+2,FALSE) -> 5 | G48: =VLOOKUP(A48,$O$107:$AM$138,B48+1,FALSE) -> 1 | H48: =VLOOKUP(A48,$O$142:$AM$173,B48+1,FALSE) -> 0 | I48: =VLOOKUP(A48,$O$40:$AN$70,B48+2,FALSE) -> 1 | J48: =VLOOKUP(A48,$O$73:$AN$104,B48+2,FALSE) -> 0 | K48: =VLOOKUP(A48,$O$175:$AM$206,B48+1,FALSE) -> 6 | L48: ='Aztec Metered Load'!C52 -> 4.16 | O48: =O12 -> 45756 | P48: 4 | Q48: 1 | R48: 1 | S48: 2 | T48: 2 | U48: 2 | V48: 2 | W48: 1 | X48: 1 | Y48: 1 | Z48: 1 | AA48: 1 | AB48: 1 | AC48: 1 | AD48: 1 | AE48: 1 | AF48: 1 | AG48: 1 | AH48: 1 | AI48: 1 | AJ48: 1 | AK48: 1 | AL48: 1 | AM48: 1 | AN48: 1 | AO48: =SUM(Q48:AN48) -> 28 | AP48: =IF(P48="SUNDAY",0,SUM(X48:AM48)) -> 16 | AQ48: =IF(P48="SUNDAY",SUM(Q48:AN48),SUM(Q48:W48,AN48:AN48)) -> 12
A49: =IF(B48=24,A48+1,A48) -> 45749 | B49: =IF(B48=24,1,B48+1) -> 23 | C49: =IFERROR(MATCH(A50,NERCHolidays!$B$2:$B$121,0),0) -> 0 | D49: =IF(AND(B49>=8,B49<=23),1,0) -> 1 | E49: =IF(OR(WEEKDAY(A49)=1,C49<>0),"OP",IF(D49=0,"OP","PK")) -> PK | F49: =VLOOKUP(A49,$O$3:$AN$34,B49+2,FALSE) -> 5 | G49: =VLOOKUP(A49,$O$107:$AM$138,B49+1,FALSE) -> 1 | H49: =VLOOKUP(A49,$O$142:$AM$173,B49+1,FALSE) -> 0 | I49: =VLOOKUP(A49,$O$40:$AN$70,B49+2,FALSE) -> 1 | J49: =VLOOKUP(A49,$O$73:$AN$104,B49+2,FALSE) -> 0 | K49: =VLOOKUP(A49,$O$175:$AM$206,B49+1,FALSE) -> 6 | L49: ='Aztec Metered Load'!C53 -> 3.934 | O49: =O13 -> 45757 | P49: 5 | Q49: 1 | R49: 1 | S49: 2 | T49: 2 | U49: 2 | V49: 2 | W49: 1 | X49: 1 | Y49: 1 | Z49: 1 | AA49: 1 | AB49: 1 | AC49: 1 | AD49: 1 | AE49: 1 | AF49: 1 | AG49: 1 | AH49: 1 | AI49: 1 | AJ49: 1 | AK49: 1 | AL49: 1 | AM49: 1 | AN49: 1 | AO49: =SUM(Q49:AN49) -> 28 | AP49: =IF(P49="SUNDAY",0,SUM(X49:AM49)) -> 16 | AQ49: =IF(P49="SUNDAY",SUM(Q49:AN49),SUM(Q49:W49,AN49:AN49)) -> 12
...

Sheet pivot Allocation
A3: Row Labels | B3: Sum of AHP | C3: Sum of WRP | D3: Sum of Total
A4: 42644 | B4: 25 | C4: 0 | D4: 78
A5: 42645 | B5: 24 | C5: 0 | D5: 77
A6: 42646 | B6: 25 | C6: 0 | D6: 89
A7: 42647 | B7: 24 | C7: 0 | D7: 87
A8: 42648 | B8: 24 | C8: 0 | D8: 86
A9: 42649 | B9: 24 | C9: 0 | D9: 86
A10: 42650 | B10: 24 | C10: 0 | D10: 77
A11: 42651 | B11: 24 | C11: 0 | D11: 76
A12: 42652 | B12: 24 | C12: 0 | D12: 77
A13: 42653 | B13: 24 | C13: 0 | D13: 75
A14: 42654 | B14: 24 | C14: 0 | D14: 75
A15: 42655 | B15: 24 | C15: 0 | D15: 102
... A34: 42674 | B34: 24 | C34: 0 | D34: 93
A35: Grand Total | B35: 746 | C35: 0 | D35: 2800

Sheet NERCHolidays
A1: NERCHoliday | B1: Date | C1: Weekday
A2: New Year's Day | B2: 40544 | C2: Sat
A3: Memorial Day | B3: 40693 | C3: Mon
A4: Independence Day | B4: 40728 | C4: Mon
A5: Labor Day | B5: 40791 | C5: Mon
A6: Thanksgivig Day | B6: 40871 | C6: Thu
A7: Christmas Day | B7: 40903 | C7: Mon
A8: New Year's Day | B8: 40910 | C8: Mon
A9: Memorial Day | B9: 41057 | C9: Mon
A10: Independence Day | B10: 41094 | C10: Wed
A11: Labor Day | B11: 41155 | C11: Mon
A12: Thanksgivig Day | B12: 41235 | C12: Thu
A13: Christmas Day | B13: 41268 | C13: Tue
... A121: Christmas Day | B121: 47842 | C121: Wed

Sheet WRP Cost
B2: Month | C2: ATC | D2: PK | E2: OP | F2: Note | G2: ATC Hours | H2: PK Hours | I2: OP Hours | J2: Scheduled PK | K2: Scheduled OP | L2: WRP Cost ($/MWh)
B3: 42522 | C3: =SUMPRODUCT(D3:E3,H3:I3)/G3 -> 34.218444 | D3: 35.92 | E3: 31.89 | F3: Final | G3: 720 | H3: 416 | I3: 304
B4: 42552 | C4: =SUMPRODUCT(D4:E4,H4:I4)/G4 -> 36.675161 | D4: 42.39 | E4: 30.03 | F4: Final | G4: 744 | H4: 400 | I4: 344
B5: 42583 | C5: =SUMPRODUCT(D5:E5,H5:I5)/G5 -> 32.91 | D5: 37.46 | E5: 26.61 | F5: Estimated | G5: 744 | H5: 432 | I5: 312
B6: 42614 | C6: =SUMPRODUCT(D6:E6,H6:I6)/G6 -> 31.677778 | D6: 38.3 | E6: 23.4 | F6: Estimated | G6: 720 | H6: 400 | I6: 320
B7: 42644 | F7: Estimated | G7: 744 | H7: 416 | I7: 328

Sheet Global
A1: Energy Imbalance Global
B3: Date/time beginning | C3: 44409 | D3: =(DATE(YEAR(C3), MONTH(C3)+1,1)-DATE(YEAR(C3), MONTH(C3), 1))*24 -> 744
B4: BILLING PHASE | D4: Preliminary
B5: TRANSMISSION LOSSES (L-AS7) | D5: 0.045
B7: 1st Deviation Bandwidth (L-AS4 and L-AS9)
B8: Bandwidth percentage, over or under (less than or equal to 1.5%) or | D8: 0.015
B9: Bandwidth minimum, MW | C9: 4
B10: Credit Factor for In-Band Over Delivery | D10: 1
B11: Debit Factor for In-Band Under Delivery | D11: 1
B13: 2nd Deviation Bandwidth (L-AS4 and L-AS9)
B14: Bandwidth percentage, over or under (1.5% to 7.5%) or | C14: 0.015 | D14: 0.075
B15: Bandwidth minimum/maximum, MW | C15: 4 | D15: 10
B16: Credit Factor for Out-of-Band Over Delivery | D16: 0.9
B17: Debit Factor for Out-of-Band Under Delivery | D17: 1.1
B19: 3rd Deviation Bandwidth (L-AS4 and L-AS9)
B20: Bandwidth percentage, over or under (greater than 7.5%) or | C20: 0.075
B21: Bandwidth maximum, MW | D21: 10
B22: Credit Factor for Out-of-Band Over Delivery | D22: 0.75
B23: Debit Factor for Out-of-Band Under Delivery | D23: 1.25
B25: Note: Intermittent generators are exempt from 25% penalties. All intermittent generation imbalances greater than 1.5% of metered generation are subject only to a 10% penalty.

Sheet Resources
A1: CUSTOMER'S SCHEDULED RESOURCES
A5: HOUR BEGINS | B5: HOUR ENDS | C5: PAGE WACM NET RESOURCES (MWh)
A7: 44531 | B7: =$A7+1/24 -> 44531.042 | C7: =GEServed!K3 -> 6
A8: =$A7+1/24 -> 44531.042 | B8: =$A8+1/24 -> 44531.083 | C8: =GEServed!K4 -> 6
A9: =$A8+1/24 -> 44531.083 | B9: =$A9+1/24 -> 44531.125 | C9: =GEServed!K5 -> 1
A10: =$A9+1/24 -> 44531.125 | B10: =$A10+1/24 -> 44531.167 | C10: =GEServed!K6 -> 6
A11: =$A10+1/24 -> 44531.167 | B11: =$A11+1/24 -> 44531.208 | C11: =GEServed!K7 -> 6
A12: =$A11+1/24 -> 44531.208 | B12: =$A12+1/24 -> 44531.25 | C12: =GEServed!K8 -> 6
A13: =$A12+1/24 -> 44531.25 | B13: =$A13+1/24 -> 44531.292 | C13: =GEServed!K9 -> 6
A14: =$A13+1/24 -> 44531.292 | B14: =$A14+1/24 -> 44531.333 | C14: =GEServed!K10 -> 6
A15: =$A14+1/24 -> 44531.333 | B15: =$A15+1/24 -> 44531.375 | C15: =GEServed!K11 -> 6
A16: =$A15+1/24 -> 44531.375 | B16: =$A16+1/24 -> 44531.417 | C16: =GEServed!K12 -> 5
A17: =$A16+1/24 -> 44531.417 | B17: =$A17+1/24 -> 44531.458 | C17: =GEServed!K13 -> 5
A18: =$A17+1/24 -> 44531.458 | B18: =$A18+1/24 -> 44531.5 | C18: =GEServed!K14 -> 5
A19: =$A18+1/24 -> 44531.5 | B19: =$A19+1/24 -> 44531.542 | C19: =GEServed!K15 -> 5
... A726: =$A725+1/24 -> 44560.958 | B726: =$A726+1/24 -> 44561 | C726: =GEServed!K722 -> 4
A727: =$A726+1/24 -> 44561 | B727: =$A727+1/24 -> 44561.042 | C727: =GEServed!#REF! -> #REF!
A728: =$A727+1/24 -> 44561.042 | B728: =$A728+1/24 -> 44561.083 | C728: =GEServed!#REF! -> #REF!
A729: =$A728+1/24 -> 44561.083 | B729: =$A729+1/24 -> 44561.125 | C729: =GEServed!#REF! -> #REF!
A730: =$A729+1/24 -> 44561.125 | B730: =$A730+1/24 -> 44561.167 | C730: =GEServed!#REF! -> #REF!
A731: =$A730+1/24 -> 44561.167 | B731: =$A731+1/24 -> 44561.208 | C731: =GEServed!#REF! -> #REF!
A732: =$A731+1/24 -> 44561.208 | B732: =$A732+1/24 -> 44561.25 | C732: =GEServed!#REF! -> #REF!
A733: =$A732+1/24 -> 44561.25 | B733: =$A733+1/24 -> 44561.292 | C733: =GEServed!#REF! -> #REF!
A734: =$A733+1/24 -> 44561.292 | B734: =$A734+1/24 -> 44561.333 | C734: =GEServed!#REF! -> #REF!
A735: =$A734+1/24 -> 44561.333 | B735: =$A735+1/24 -> 44561.375 | C735: =GEServed!#REF! -> #REF!
A736: =$A735+1/24 -> 44561.375 | B736: =$A736+1/24 -> 44561.417 | C736: =GEServed!#REF! -> #REF!
A737: =$A736+1/24 -> 44561.417 | B737: =$A737+1/24 -> 44561.458 | C737: =GEServed!#REF! -> #REF!
A738: =$A737+1/24 -> 44561.458 | B738: =$A738+1/24 -> 44561.5 | C738: =GEServed!#REF! -> #REF!
... A750: =$A749+1/24 -> 44561.958 | B750: =$A750+1/24 -> 44562 | C750: =GEServed!#REF! -> #REF!

Sheet Pricing
C1: AGGREGATE PRICING
K4: Prices are from Oati website
C5: HOUR BEGINS | D5: HOUR ENDS | E5: PRICING
A6: Date | B6: HE | K6: =A7 -> 44531 | L6: 25 | M6: 25 | N6: 25 | O6: 25 | P6: 25 | Q6: 25 | R6: 25 | S6: 25 | T6: 25 | U6: 25 | V6: 25 | W6: 25 | X6: 25 | Y6: 25 | Z6: 25 | AA6: 25 | AB6: 25 | AC6: 25 | AD6: 25 | AE6: 25 | AF6: 25 | AG6: 25 | AH6: 25 | AI6: 25
A7: 44531 | B7: =HOUR(C7)+1 -> 1 | C7: 44531 | D7: =$C7+1/24 -> 44531.042 | E7: =VLOOKUP(A7,$K$6:$AI$36,B7+1,FALSE) -> 25 | K7: =K6+1 -> 44532 | L7: 25.29 | M7: 25.29 | N7: 25.29 | O7: 25.29 | P7: 20 | Q7: 25 | R7: 30 | S7: 35 | T7: 27.36 | U7: 27.36 | V7: 24 | W7: 27.36 | X7: 27.36 | Y7: 27.36 | Z7: 27.36 | AA7: 27.36 | AB7: 25 | AC7: 27.36 | AD7: 27.36 | AE7: 27.36 | AF7: 27.36 | AG7: 27.36 | AH7: 27.36 | AI7: 25.29
A8: =DATE(YEAR(C8),MONTH(C8),DAY(C8)) -> 44531 | B8: =HOUR(C8)+1 -> 2 | C8: =$C7+1/24 -> 44531.042 | D8: =$C8+1/24 -> 44531.083 | E8: =VLOOKUP(A8,$K$6:$AI$36,B8+1,FALSE) -> 25 | K8: =K7+1 -> 44533 | L8: 29.58 | M8: 29.58 | N8: 29.58 | O8: 29.58 | P8: 29.58 | Q8: 29.58 | R8: 18 | S8: 18 | T8: 25.4 | U8: 35 | V8: 35 | W8: 29.58 | X8: 29.58 | Y8: 29.58 | Z8: 35 | AA8: 29.58 | AB8: 45 | AC8: 29.58 | AD8: 29.58 | AE8: 29.58 | AF8: 29.58 | AG8: 29.58 | AH8: 29.58 | AI8: 29.58
A9: =DATE(YEAR(C9),MONTH(C9),DAY(C9)) -> 44531 | B9: =HOUR(C9)+1 -> 3 | C9: =$C8+1/24 -> 44531.083 | D9: =$C9+1/24 -> 44531.125 | E9: =VLOOKUP(A9,$K$6:$AI$36,B9+1,FALSE) -> 25 | K9: =K8+1 -> 44534 | L9: 30 | M9: 30 | N9: 30 | O9: 30 | P9: 30 | Q9: 30 | R9: 30 | S9: 30 | T9: 30 | U9: 30 | V9: 30 | W9: 30 | X9: 30 | Y9: 30 | Z9: 30 | AA9: 30 | AB9: 30 | AC9: 30 | AD9: 30 | AE9: 30 | AF9: 30 | AG9: 30 | AH9: 30 | AI9: 30
A10: =DATE(YEAR(C10),MONTH(C10),DAY(C10)) -> 44531 | B10: =HOUR(C10)+1 -> 4 | C10: =$C9+1/24 -> 44531.125 | D10: =$C10+1/24 -> 44531.167 | E10: =VLOOKUP(A10,$K$6:$AI$36,B10+1,FALSE) -> 25 | K10: =K9+1 -> 44535 | L10: 30.21 | M10: 30.21 | N10: 30.21 | O10: 30.21 | P10: 30.21 | Q10: 30.21 | R10: 30.21 | S10: 30 | T10: 30 | U10: 30 | V10: 30 | W10: 30 | X10: 30 | Y10: 30 | Z10: 30 | AA10: 30 | AB10: 30 | AC10: 30 | AD10: 30 | AE10: 30 | AF10: 30 | AG10: 30 | AH10: 30 | AI10: 30.21
A11: =DATE(YEAR(C11),MONTH(C11),DAY(C11)) -> 44531 | B11: =HOUR(C11)+1 -> 5 | C11: =$C10+1/24 -> 44531.167 | D11: =$C11+1/24 -> 44531.208 | E11: =VLOOKUP(A11,$K$6:$AI$36,B11+1,FALSE) -> 25 | K11: =K10+1 -> 44536 | L11: 21.13 | M11: 21.13 | N11: 21.13 | O11: 21.13 | P11: 18 | Q11: 22 | R11: 22 | S11: 22 | T11: 20 | U11: 20 | V11: 20 | W11: 20 | X11: 20.62 | Y11: 20.62 | Z11: 20.62 | AA11: 20 | AB11: 20.62 | AC11: 24 | AD11: 20.62 | AE11: 20.62 | AF11: 20.62 | AG11: 20.62 | AH11: 20.62 | AI11: 21.13
A12: =DATE(YEAR(C12),MONTH(C12),DAY(C12)) -> 44531 | B12: =HOUR(C12)+1 -> 6 | C12: =$C11+1/24 -> 44531.208 | D12: =$C12+1/24 -> 44531.25 | E12: =VLOOKUP(A12,$K$6:$AI$36,B12+1,FALSE) -> 25 | K12: =K11+1 -> 44537 | L12: 50.35 | M12: 50.35 | N12: 26 | O12: 50.35 | P12: 28 | Q12: 45 | R12: 75 | S12: 75 | T12: 39.38 | U12: 35 | V12: 75 | W12: 54.6 | X12: 30 | Y12: 54 | Z12: 54 | AA12: 54 | AB12: 44.43 | AC12: 50 | AD12: 54 | AE12: 54 | AF12: 54 | AG12: 54 | AH12: 54 | AI12: 50.35
A13: =DATE(YEAR(C13),MONTH(C13),DAY(C13)) -> 44531 | B13: =HOUR(C13)+1 -> 7 | C13: =$C12+1/24 -> 44531.25 | D13: =$C13+1/24 -> 44531.292 | E13: =VLOOKUP(A13,$K$6:$AI$36,B13+1,FALSE) -> 25 | K13: =K12+1 -> 44538 | L13: 30 | M13: 30 | N13: 30 | O13: 30 | P13: 30 | Q13: 30 | R13: 30 | S13: 33.5 | T13: 33.5 | U13: 33.5 | V13: 33.5 | W13: 33.5 | X13: 33.5 | Y13: 33.5 | Z13: 33.5 | AA13: 33.5 | AB13: 33.5 | AC13: 33.5 | AD13: 33.5 | AE13: 33.5 | AF13: 33.5 | AG13: 33.5 | AH13: 33.5 | AI13: 30
